Workbook

Sheet Zoneamento Curitiba
A1: Nome da Zona | B1: Sigla | C1: Sigla_gis | D1: Tipo de Uso | E1: Usos | F1: Permissibilidade | G1: Coef. Aproveitamento Básico | H1: Coef. Aproveitamento Permissível | I1: Altura Básica (pav) | J1: Altura Permissível (pav) | K1: Porte Básico (m²) | L1: Porte Permissível (m²) | M1: Taxa de Ocupação (%) | N1: Recuo (m) | O1: Taxa Permeabilidade (%) | P1: Afastamento Divisa (m) | Q1: Lote Padrão (m²) | R1: Observações
A2: Setor das Vias Setoriais 1 | B2: SVS-1 | C2: {=IFERROR(IF(XLOOKUP(B2,Planilha1!$B:$B,Planilha1!$C:$C)=0,"",XLOOKUP(B2,Planilha1!$B:$B,Planilha1!$C:$C)),"")} | D2: Habitacional | E2: Habitações Unifamiliares, Habitação Coletiva, Habitações Unifamiliares em série, Habitação Institucional, Habitação Transitória 1 | F2: Permitido | G2: 1 | R2: Hab. unif. em série: somente transversais ao alinhamento
A3: Setor das Vias Setoriais 1 | B3: SVS-1 | C3: {=IFERROR(IF(XLOOKUP(B3,Planilha1!$B:$B,Planilha1!$C:$C)=0,"",XLOOKUP(B3,Planilha1!$B:$B,Planilha1!$C:$C)),"")} | D3: Não Habitacional | E3: Posto de Abastecimento | F3: Permitido | G3: 1 | R3: Atendida regulamentação específica
A4: Setor das Vias Setoriais 1 | B4: SVS-1 | C4: {=IFERROR(IF(XLOOKUP(B4,Planilha1!$B:$B,Planilha1!$C:$C)=0,"",XLOOKUP(B4,Planilha1!$B:$B,Planilha1!$C:$C)),"")} | D4: Não Habitacional | E4: Estacionamento Comercial, Edifício Garagem | F4: Permitido | G4: 1 | R4: Obrigatório comércio/serviço no térreo, min 50% testada
A5: Setor das Vias Setoriais 1 | B5: SVS-1 | C5: {=IFERROR(IF(XLOOKUP(B5,Planilha1!$B:$B,Planilha1!$C:$C)=0,"",XLOOKUP(B5,Planilha1!$B:$B,Planilha1!$C:$C)),"")} | D5: Não Habitacional | E5: Comunitário 1 e 2 | F5: Permitido | G5: 1 | K5: 2.000,00 | L5: 10.000,00 | R5: Atendido coef e porte - primeiro atingido
A6: Setor das Vias Setoriais 1 | B6: SVS-1 | C6: {=IFERROR(IF(XLOOKUP(B6,Planilha1!$B:$B,Planilha1!$C:$C)=0,"",XLOOKUP(B6,Planilha1!$B:$B,Planilha1!$C:$C)),"")} | D6: Não Habitacional | E6: Comunitário 3 | F6: Permissível | L6: 10.000,00 | R6: Somente permissível
A7: Setor das Vias Setoriais 1 | B7: SVS-1 | C7: {=IFERROR(IF(XLOOKUP(B7,Planilha1!$B:$B,Planilha1!$C:$C)=0,"",XLOOKUP(B7,Planilha1!$B:$B,Planilha1!$C:$C)),"")} | D7: Não Habitacional | E7: Comércio e Serviço Vicinal, de Bairro e Setorial | F7: Permitido | G7: 1 | K7: 5.000,00 | L7: Acima de 5.000,00
A8: Setor das Vias Setoriais 1 | B8: SVS-1 | C8: {=IFERROR(IF(XLOOKUP(B8,Planilha1!$B:$B,Planilha1!$C:$C)=0,"",XLOOKUP(B8,Planilha1!$B:$B,Planilha1!$C:$C)),"")} | D8: Não Habitacional | E8: Indústria tipo 1 | F8: Permitido | K8: 200,00 | L8: 400,00 | R8: Admitido alvará em edificação existente
A9: Setor das Vias Setoriais 2 | B9: SVS-2 | C9: {=IFERROR(IF(XLOOKUP(B9,Planilha1!$B:$B,Planilha1!$C:$C)=0,"",XLOOKUP(B9,Planilha1!$B:$B,Planilha1!$C:$C)),"")} | D9: Habitacional | E9: Habitações Unifamiliares, Habitação Coletiva, Habitação Institucional, Habitações Unifamiliares em série, Habitação Transitória 1 | F9: Permitido | G9: 1 | I9: 2 | M9: 50 | N9: 5 | O9: 25 | R9: Hab. unif. em série: somente transversais
A10: Setor das Vias Setoriais 2 | B10: SVS-2 | C10: {=IFERROR(IF(XLOOKUP(B10,Planilha1!$B:$B,Planilha1!$C:$C)=0,"",XLOOKUP(B10,Planilha1!$B:$B,Planilha1!$C:$C)),"")} | D10: Não Habitacional | E10: Posto de Abastecimento | F10: Permitido | G10: 1 | R10: Atendida regulamentação específica
A11: Setor das Vias Setoriais 2 | B11: SVS-2 | C11: {=IFERROR(IF(XLOOKUP(B11,Planilha1!$B:$B,Planilha1!$C:$C)=0,"",XLOOKUP(B11,Planilha1!$B:$B,Planilha1!$C:$C)),"")} | D11: Não Habitacional | E11: Estacionamento Comercial, Edifício Garagem | F11: Permitido | G11: 1 | R11: Obrigatório comércio/serviço no térreo, min 50% testada
A12: Setor das Vias Setoriais 2 | B12: SVS-2 | C12: {=IFERROR(IF(XLOOKUP(B12,Planilha1!$B:$B,Planilha1!$C:$C)=0,"",XLOOKUP(B12,Planilha1!$B:$B,Planilha1!$C:$C)),"")} | D12: Não Habitacional | E12: Comunitário 1 | F12: Permitido | G12: 1 | I12: 2 | M12: 50 | N12: 5 | O12: 25
A13: Setor das Vias Setoriais 2 | B13: SVS-2 | C13: {=IFERROR(IF(XLOOKUP(B13,Planilha1!$B:$B,Planilha1!$C:$C)=0,"",XLOOKUP(B13,Planilha1!$B:$B,Planilha1!$C:$C)),"")} | D13: Não Habitacional | E13: Comunitário 2 e 3 exceto Ensino | F13: Permitido | G13: 1 | I13: 2 | K13: 2.000,00 | L13: 5.000,00 | M13: 50 | N13: 5 | O13: 25
A14: Setor das Vias Setoriais 2 | B14: SVS-2 | C14: {=IFERROR(IF(XLOOKUP(B14,Planilha1!$B:$B,Planilha1!$C:$C)=0,"",XLOOKUP(B14,Planilha1!$B:$B,Planilha1!$C:$C)),"")} | D14: Não Habitacional | E14: Comércio e Serviço Vicinal, de Bairro e Setorial | F14: Permitido | G14: 1 | I14: 2 | K14: 2.000,00 | L14: 5.000,00 | M14: 50 | N14: 5 | O14: 25
A15: Setor das Vias Setoriais 2 | B15: SVS-2 | C15: {=IFERROR(IF(XLOOKUP(B15,Planilha1!$B:$B,Planilha1!$C:$C)=0,"",XLOOKUP(B15,Planilha1!$B:$B,Planilha1!$C:$C)),"")} | D15: Não Habitacional | E15: Indústria Tipo 1 | F15: Permitido | K15: 200,00 | L15: 400,00 | R15: Admitido alvará em edificação existente
A16: Setor das Vias Coletoras 1 | B16: SVC-1 | C16: {=IFERROR(IF(XLOOKUP(B16,Planilha1!$B:$B,Planilha1!$C:$C)=0,"",XLOOKUP(B16,Planilha1!$B:$B,Planilha1!$C:$C)),"")} | D16: Habitacional | E16: Habitações Unifamiliares, Habitação Coletiva, Habitação Institucional, Habitações Unifamiliares em série, Habitação Transitória 1 | F16: Permitido | G16: 1 | I16: 2 | M16: 50 | N16: 5 | O16: 25 | R16: Hab. unif. em série: somente transversais
A17: Setor das Vias Coletoras 1 | B17: SVC-1 | C17: {=IFERROR(IF(XLOOKUP(B17,Planilha1!$B:$B,Planilha1!$C:$C)=0,"",XLOOKUP(B17,Planilha1!$B:$B,Planilha1!$C:$C)),"")} | D17: Não Habitacional | E17: Posto de Abastecimento | F17: Permitido | G17: 1 | R17: Atendida regulamentação específica
A18: Setor das Vias Coletoras 1 | B18: SVC-1 | C18: {=IFERROR(IF(XLOOKUP(B18,Planilha1!$B:$B,Planilha1!$C:$C)=0,"",XLOOKUP(B18,Planilha1!$B:$B,Planilha1!$C:$C)),"")} | D18: Não Habitacional | E18: Estacionamento Comercial, Edifício Garagem | F18: Permitido | G18: 1 | R18: Obrigatório comércio/serviço no térreo, min 50% testada
A19: Setor das Vias Coletoras 1 | B19: SVC-1 | C19: {=IFERROR(IF(XLOOKUP(B19,Planilha1!$B:$B,Planilha1!$C:$C)=0,"",XLOOKUP(B19,Planilha1!$B:$B,Planilha1!$C:$C)),"")} | D19: Não Habitacional | E19: Comunitário 1, Comunitário 2 - Culto religioso | F19: Permitido | G19: 1 | I19: 2 | K19: 5.000,00 | L19: 10.000,00 | M19: 50 | N19: 5 | O19: 25
A20: Setor das Vias Coletoras 1 | B20: SVC-1 | C20: {=IFERROR(IF(XLOOKUP(B20,Planilha1!$B:$B,Planilha1!$C:$C)=0,"",XLOOKUP(B20,Planilha1!$B:$B,Planilha1!$C:$C)),"")} | D20: Não Habitacional | E20: Comunitário 2 (exceto culto) e 3 | F20: Permissível | M20: 50 | N20: 5 | O20: 25 | R20: Somente permissível
A21: Setor das Vias Coletoras 1 | B21: SVC-1 | C21: {=IFERROR(IF(XLOOKUP(B21,Planilha1!$B:$B,Planilha1!$C:$C)=0,"",XLOOKUP(B21,Planilha1!$B:$B,Planilha1!$C:$C)),"")} | D21: Não Habitacional | E21: Comércio e Serviço Vicinal, de Bairro e Setorial | F21: Permitido | G21: 1 | I21: 2 | K21: 2.000,00 | L21: 5.000,00 | M21: 50 | N21: 5 | O21: 25
A22: Setor das Vias Coletoras 1 | B22: SVC-1 | C22: {=IFERROR(IF(XLOOKUP(B22,Planilha1!$B:$B,Planilha1!$C:$C)=0,"",XLOOKUP(B22,Planilha1!$B:$B,Planilha1!$C:$C)),"")} | D22: Não Habitacional | E22: Indústria Tipo 1 | F22: Permitido | K22: 200,00 | L22: 400 | R22: Admitido alvará em edificação existente
A23: Setor das Vias Coletoras 2 | B23: SVC-2 | C23: {=IFERROR(IF(XLOOKUP(B23,Planilha1!$B:$B,Planilha1!$C:$C)=0,"",XLOOKUP(B23,Planilha1!$B:$B,Planilha1!$C:$C)),"")} | D23: Habitacional | E23: Habitações Unifamiliares, Habitação Coletiva, Habitação Institucional, Habitações Unifamiliares em série, Habitação Transitória 1 | F23: Permitido | G23: 1 | I23: 2 | M23: 50 | N23: 5 | O23: 25 | R23: Hab. unif. em série: somente transversais
A24: Setor das Vias Coletoras 2 | B24: SVC-2 | C24: {=IFERROR(IF(XLOOKUP(B24,Planilha1!$B:$B,Planilha1!$C:$C)=0,"",XLOOKUP(B24,Planilha1!$B:$B,Planilha1!$C:$C)),"")} | D24: Não Habitacional | E24: Posto de Abastecimento | F24: Permitido | G24: 1 | R24: Atendida regulamentação específica
A25: Setor das Vias Coletoras 2 | B25: SVC-2 | C25: {=IFERROR(IF(XLOOKUP(B25,Planilha1!$B:$B,Planilha1!$C:$C)=0,"",XLOOKUP(B25,Planilha1!$B:$B,Planilha1!$C:$C)),"")} | D25: Não Habitacional | E25: Estacionamento Comercial, Edifício Garagem | F25: Permitido | G25: 1 | R25: Obrigatório comércio/serviço no térreo, min 50% testada
A26: Setor das Vias Coletoras 2 | B26: SVC-2 | C26: {=IFERROR(IF(XLOOKUP(B26,Planilha1!$B:$B,Planilha1!$C:$C)=0,"",XLOOKUP(B26,Planilha1!$B:$B,Planilha1!$C:$C)),"")} | D26: Não Habitacional | E26: Comunitário 1 e 2 | F26: Permitido | G26: 1 | I26: 2 | K26: 400,00 | L26: 2.000,00 | M26: 50 | N26: 5 | O26: 25
A27: Setor das Vias Coletoras 2 | B27: SVC-2 | C27: {=IFERROR(IF(XLOOKUP(B27,Planilha1!$B:$B,Planilha1!$C:$C)=0,"",XLOOKUP(B27,Planilha1!$B:$B,Planilha1!$C:$C)),"")} | D27: Não Habitacional | E27: Comércio e Serviço Vicinal, de Bairro e Setorial | F27: Permitido | G27: 1 | I27: 2 | K27: 1.000,00 | L27: 2.000,00 | M27: 50 | N27: 5 | O27: 25
A28: Setor das Vias Coletoras 2 | B28: SVC-2 | C28: {=IFERROR(IF(XLOOKUP(B28,Planilha1!$B:$B,Planilha1!$C:$C)=0,"",XLOOKUP(B28,Planilha1!$B:$B,Planilha1!$C:$C)),"")} | D28: Não Habitacional | E28: Indústria Tipo 1 | F28: Permitido | K28: 200,00 | L28: 400,00 | R28: Admitido alvará em edificação existente
A29: Setor das Vias Prioritárias | B29: SVP | C29: {=IFERROR(IF(XLOOKUP(B29,Planilha1!$B:$B,Planilha1!$C:$C)=0,"",XLOOKUP(B29,Planilha1!$B:$B,Planilha1!$C:$C)),"")} | D29: Habitacional | E29: Habitações Unifamiliares | F29: Permitido | R29: Até 3 habitações unifamiliares por lote
A30: Setor das Vias Prioritárias | B30: SVP | C30: {=IFERROR(IF(XLOOKUP(B30,Planilha1!$B:$B,Planilha1!$C:$C)=0,"",XLOOKUP(B30,Planilha1!$B:$B,Planilha1!$C:$C)),"")} | D30: Habitacional | E30: Habitações Unifamiliares em série | F30: Permitido | R30: Somente transversais ao alinhamento predial
A31: Setor das Vias Prioritárias | B31: SVP | C31: {=IFERROR(IF(XLOOKUP(B31,Planilha1!$B:$B,Planilha1!$C:$C)=0,"",XLOOKUP(B31,Planilha1!$B:$B,Planilha1!$C:$C)),"")} | D31: Habitacional | E31: Habitação Coletiva, Habitação Transitória 1 | F31: Permitido | R31: Apart-hotel sem centro de convenções
A32: Setor das Vias Prioritárias | B32: SVP | C32: {=IFERROR(IF(XLOOKUP(B32,Planilha1!$B:$B,Planilha1!$C:$C)=0,"",XLOOKUP(B32,Planilha1!$B:$B,Planilha1!$C:$C)),"")} | D32: Não Habitacional | E32: Posto de Abastecimento | F32: Permitido | R32: Proibido em esquinas VP x VP e VP x Via Externa EE
A33: Setor das Vias Prioritárias | B33: SVP | C33: {=IFERROR(IF(XLOOKUP(B33,Planilha1!$B:$B,Planilha1!$C:$C)=0,"",XLOOKUP(B33,Planilha1!$B:$B,Planilha1!$C:$C)),"")} | D33: Não Habitacional | E33: Estacionamento Comercial | F33: Permitido | R33: Obrigatório comércio/serviço vicinal/bairro no térreo, min 50% testada
A34: Setor das Vias Prioritárias | B34: SVP | C34: {=IFERROR(IF(XLOOKUP(B34,Planilha1!$B:$B,Planilha1!$C:$C)=0,"",XLOOKUP(B34,Planilha1!$B:$B,Planilha1!$C:$C)),"")} | D34: Não Habitacional | E34: Comércio e Serviço Vicinal e de Bairro | F34: Permitido | K34: 200 | R34: Permitido alvará até 200m² em edif. existente sem estacionamento. Acima: consultar CMU
A35: Zona Central | B35: ZC | C35: {=IFERROR(IF(XLOOKUP(B35,Planilha1!$B:$B,Planilha1!$C:$C)=0,"",XLOOKUP(B35,Planilha1!$B:$B,Planilha1!$C:$C)),"")} -> ZC | D35: Habitacional | E35: Habitação Unifamiliar | F35: Permitido | G35: 1 | I35: 2 | M35: 50 | O35: 25 | Q35: 11x330 | R35: Uma habitação unifamiliar por lote
A36: Zona Central | B36: ZC | C36: {=IFERROR(IF(XLOOKUP(B36,Planilha1!$B:$B,Planilha1!$C:$C)=0,"",XLOOKUP(B36,Planilha1!$B:$B,Planilha1!$C:$C)),"")} -> ZC | D36: Habitacional | E36: Habitação Coletiva, Habitação Institucional, Habitação Transitória 1, Empreendimento inclusivo de habitação de interesse social | F36: Permitido | G36: 5 | I36: livre | M36: Subsolo, térreo e 2º pav = 100%; demais pav = 66% | N36: Alinhamento predial | O36: Obrigatório mecanismo contenção cheias | P36: 2 | Q36: 11x330 | R36: Proibido balanço sobre passeio, permitido marquise max 1,20m
A37: Zona Central | B37: ZC | C37: {=IFERROR(IF(XLOOKUP(B37,Planilha1!$B:$B,Planilha1!$C:$C)=0,"",XLOOKUP(B37,Planilha1!$B:$B,Planilha1!$C:$C)),"")} -> ZC | D37: Não Habitacional | E37: Comunitário 1 | F37: Permitido | G37: 5 | I37: livre | M37: Subsolo, térreo e 2º pav = 100%; demais pav = 66% | N37: Alinhamento predial | O37: Obrigatório mecanismo contenção cheias | P37: 2 | Q37: 11x330
A38: Zona Central | B38: ZC | C38: {=IFERROR(IF(XLOOKUP(B38,Planilha1!$B:$B,Planilha1!$C:$C)=0,"",XLOOKUP(B38,Planilha1!$B:$B,Planilha1!$C:$C)),"")} -> ZC | D38: Não Habitacional | E38: Comunitário 2 - Lazer, Cultura e Culto Religioso, Comércio e Serviço Vicinal, de Bairro e Setorial, Edifício Garagem | F38: Permitido | G38: 4 | I38: livre | M38: Subsolo, térreo e 2º pav = 100%; demais pav = 66% | N38: Alinhamento predial | O38: Obrigatório mecanismo contenção cheias | P38: 2 | Q38: 11x330 | R38: Edifício Garagem: CA mínimo 1,5
A39: Zona Central | B39: ZC | C39: {=IFERROR(IF(XLOOKUP(B39,Planilha1!$B:$B,Planilha1!$C:$C)=0,"",XLOOKUP(B39,Planilha1!$B:$B,Planilha1!$C:$C)),"")} -> ZC | D39: Não Habitacional | E39: Comunitário 2 - Ensino, Comunitário 3 | F39: Permissível | G39: 4 | I39: livre | M39: Subsolo, térreo e 2º pav = 100%; demais pav = 66% | N39: Alinhamento predial | O39: Obrigatório mecanismo contenção cheias | P39: 2 | Q39: 11x330
A40: Zona Central | B40: ZC | C40: {=IFERROR(IF(XLOOKUP(B40,Planilha1!$B:$B,Planilha1!$C:$C)=0,"",XLOOKUP(B40,Planilha1!$B:$B,Planilha1!$C:$C)),"")} -> ZC | D40: Não Habitacional | E40: Indústria do Tipo 1 | F40: Permitido | K40: 200 | R40: A critério CMU até 400m²
...

Sheet Planilha1
A1: Nome da Zona | B1: Sigla | C1: SIGLA NO GIS | D1: SG_ZONA
A2: Eixo de Adensamento Engenheiro Costa Barros | B2: EACB | C2: EACB | D2: APA-IGUAÇU
A3: Eixo de Adensamento Comendador Franco | B3: EACF | C3: EACF | D3: APA-PASSAÚNA
A4: Eixo Presidente Affonso Camargo - Outras Vias | B4: EAC-OV | C4: EAC | D4: ZED-LV
A5: Eixo Presidente Affonso Camargo - Via Central | B5: EAC-VC | C5: EAC | D5: ZI-LV
A6: Eixos Conectores Leste 1, 2, 3 | B6: ECL-1/2/3 | C6: ECL-3 | D6: ZS-2-LV
A7: Eixos Conectores Oeste 1, 2, 3 e 4
A8: Eixos Conectores Sul 1 e 2 | B8: ECS-1/2 | C8: ECS-1
A9: Eixo Estrutural - Outras Vias | B9: EE-OV | C9: EE
A10: Eixo Estrutural - Via Central | B10: EE-VC | C10: EE
A11: Eixo Estrutural - Vias Externas | B11: EE-VE | C11: EE
A12: Eixo Marechal Floriano Peixoto | B12: EMF | C12: EMF
A13: Eixo Nova Curitiba - Via Central e Outras Vias | B13: ENC | C13: ENC
A14: Eixo Nova Curitiba - Vias Externas | B14: ENC-VE | C14: ENC
A15: Polo da Linha Verde | B15: POLO-LV | C15: POLO-LV
A16: Setor Habitacional de Interesse Social | B16: SEHIS | C16: SEHIS
A17: Setor Especial da Linha Verde | B17: SE-LV | C17: SE-LV
A18: Setor Preferencial de Pedestres - XV e Central | B18: SEPE-C
A19: Setor das Vias Coletoras 1 | B19: SVC-1
A20: Setor das Vias Coletoras 2 | B20: SVC-2
A21: Setor das Vias Prioritárias | B21: SVP
A22: Setor das Vias Setoriais 1 | B22: SVS-1
A23: Setor das Vias Setoriais 2 | B23: SVS-2
A24: Zona Central | B24: ZC | C24: ZC
A25: Zona Centro Cívico - Demais Vias | B25: ZCC | C25: ZCC
A26: Zona Centro Cívico - Via Cândido de Abreu | B26: ZCC-CA
A27: Zona Comercial Santa Felicidade / Zona Comercial Umbará | B27: ZCSF/ZCUM | C27: ZCSF
A28: Zona Educacional | B28: ZE | C28: ZE
A29: Zona São Francisco | B29: ZFR | C29: ZFR
A30: Zona Histórica 1 | B30: ZH-1 | C30: ZH-1
A31: Zona Histórica 2 | B31: ZH-2 | C31: ZH-2
A32: Zona Industrial | B32: ZI | C32: ZI
A33: Zona Militar | B33: ZM | C33: ZM
A34: Zona Polo de Software | B34: ZPS | C34: ZPS
A35: Zona Residencial 1 | B35: ZR-1 | C35: ZR1
A36: Zona Residencial 2 | B36: ZR-2 | C36: ZR2
A37: Zona Residencial 3 | B37: ZR-3 | C37: ZR3
A38: Zona Residencial 3 Transição | B38: ZR3-T | C38: ZR3-T
... A49: Zona de Uso Misto do Vale do Pinhão | B49: ZUMVP | C49: ZUMVP
B50: ECO-1/2/3/4 | C50: ECO-1
...
