Workbook

Sheet parametros_zone
A1: sector | B1: taxa_ocupacao | C1: coeficiente_aproveitamento | D1: gabarito | E1: permeabilidade | F1: recuo_frontal | G1: recuo_lateral | H1: recuo_fundos | I1: area_minima | J1: usos_permitidos | K1: usos_condicionados | L1: usos_proibidos
A2: SA-01 | B2: 60 | C2: 4 | D2: 45 | E2: 20 | F2: 5 | G2: 1.5 | H2: 1.5 | I2: 120 | J2: [] | K2: [] | L2: []
A3: SE-03 | B3: 60 | C3: 1 | D3: 30 | E3: 20 | F3: 5 | I3: 50 | J3: ["residencial_unifamiliar","residencial_multifamiliar","comercio_varejista_pequeno","comercio_varejista_medio","comercio_varejista_grande","comercio_atacadista_pequeno","comercio_atacadista_medio_grande","servico_transporte_armazenagem_correio","servico_alojamento_alimentacao","servico_informacao_comunicacao","servico_financeiro_seguro","industria_transformacao","infraestrutura_energia","infraestrutura_agua","infraestrutura_residuos_liquidos","infraestrutura_residuos_solidos","infraestrutura_gestao_residuos"]
A4: SA-05 | B4: 60 | C4: 2 | D4: 15 | E4: 20 | F4: 5 | I4: 50 | J4: ["residencial_unifamiliar","residencial_multifamiliar","comercio_varejista_pequeno","comercio_varejista_medio","comercio_varejista_grande","comercio_atacadista_pequeno","comercio_atacadista_medio_grande","servico_transporte_armazenagem_correio","servico_alojamento_alimentacao","servico_informacao_comunicacao","servico_financeiro_seguro","industria_transformacao","infraestrutura_energia","infraestrutura_agua","infraestrutura_residuos_liquidos","infraestrutura_residuos_solidos","infraestrutura_gestao_residuos"]
A5: AUAE | B5: 60 | C5: 1 | E5: 20 | F5: 5 | I5: 60 | J5: ["residencial_unifamiliar","residencial_multifamiliar","comercio_varejista_pequeno","comercio_varejista_medio","comercio_varejista_grande","comercio_atacadista_pequeno","comercio_atacadista_medio_grande","servico_transporte_armazenagem_correio","servico_alojamento_alimentacao","servico_informacao_comunicacao","servico_financeiro_seguro","industria_transformacao","infraestrutura_energia","infraestrutura_agua","infraestrutura_residuos_liquidos","infraestrutura_residuos_solidos","infraestrutura_gestao_residuos"] | L5: ["agricultura","industria_extrativista"]
A6: SE-06 | B6: 60 | C6: 1 | D6: 15 | E6: 20 | F6: 5 | I6: 50 | J6: ["residencial_unifamiliar","residencial_multifamiliar","comercio_varejista_pequeno","comercio_varejista_medio","comercio_varejista_grande","comercio_atacadista_pequeno","comercio_atacadista_medio_grande","servico_transporte_armazenagem_correio","servico_alojamento_alimentacao","servico_informacao_comunicacao","servico_financeiro_seguro","industria_transformacao","industria_extrativista","infraestrutura_energia","infraestrutura_agua","infraestrutura_residuos_liquidos","infraestrutura_residuos_solidos","infraestrutura_gestao_residuos"]
A7: SE-06A | B7: 60 | C7: 1 | D7: 15 | E7: 20 | F7: 5 | I7: 50 | J7: ["residencial_unifamiliar","residencial_multifamiliar","comercio_varejista_pequeno","comercio_varejista_medio","comercio_varejista_grande","comercio_atacadista_pequeno","comercio_atacadista_medio_grande","servico_transporte_armazenagem_correio","servico_alojamento_alimentacao","servico_informacao_comunicacao","servico_financeiro_seguro","industria_transformacao","infraestrutura_energia","infraestrutura_agua","infraestrutura_residuos_liquidos","infraestrutura_residuos_solidos","infraestrutura_gestao_residuos"]
A8: SE-09 | B8: 60 | C8: 2 | D8: 15 | E8: 20 | F8: 5 | I8: 50 | J8: ["residencial_unifamiliar","residencial_multifamiliar","comercio_varejista_pequeno","comercio_varejista_medio","comercio_varejista_grande","comercio_atacadista_pequeno","comercio_atacadista_medio_grande","servico_transporte_armazenagem_correio","servico_alojamento_alimentacao","servico_informacao_comunicacao","servico_financeiro_seguro","industria_transformacao","infraestrutura_energia","infraestrutura_agua","infraestrutura_residuos_liquidos","infraestrutura_residuos_solidos","infraestrutura_gestao_residuos"]
A9: SE-08 | B9: 60 | C9: 4 | D9: 30 | E9: 20 | F9: 5 | I9: 50 | J9: ["residencial_unifamiliar","residencial_multifamiliar","comercio_varejista_pequeno","comercio_varejista_medio","comercio_varejista_grande","comercio_atacadista_pequeno","comercio_atacadista_medio_grande","servico_transporte_armazenagem_correio","servico_alojamento_alimentacao","servico_informacao_comunicacao","servico_financeiro_seguro","industria_transformacao","infraestrutura_energia","infraestrutura_agua","infraestrutura_residuos_liquidos","infraestrutura_residuos_solidos","infraestrutura_gestao_residuos"]
A10: SA-04 | B10: 60 | C10: 2 | D10: 15 | E10: 20 | F10: 5 | I10: 50 | J10: ["residencial_unifamiliar","residencial_multifamiliar","comercio_varejista_pequeno","comercio_varejista_medio","comercio_varejista_grande","comercio_atacadista_pequeno","comercio_atacadista_medio_grande","servico_transporte_armazenagem_correio","servico_alojamento_alimentacao","servico_informacao_comunicacao","servico_financeiro_seguro","industria_transformacao","infraestrutura_energia","infraestrutura_agua","infraestrutura_residuos_liquidos","infraestrutura_residuos_solidos","infraestrutura_gestao_residuos"]
A11: FR | B11: 60 | C11: 1 | D11: 15 | E11: 20 | F11: 5 | I11: 50 | J11: ["residencial_unifamiliar","residencial_multifamiliar","comercio_varejista_pequeno","comercio_varejista_medio","comercio_varejista_grande","comercio_atacadista_pequeno","comercio_atacadista_medio_grande","servico_transporte_armazenagem_correio","servico_alojamento_alimentacao","servico_informacao_comunicacao","servico_financeiro_seguro","industria_transformacao","infraestrutura_energia","infraestrutura_agua","infraestrutura_residuos_liquidos","infraestrutura_residuos_solidos","infraestrutura_gestao_residuos"]
A12: SE-07 | B12: 60 | E12: 20 | F12: 5 | J12: ["residencial_unifamiliar","residencial_multifamiliar","comercio_varejista_pequeno","comercio_varejista_medio","comercio_varejista_grande","comercio_atacadista_pequeno","comercio_atacadista_medio_grande","servico_transporte_armazenagem_correio","servico_alojamento_alimentacao","servico_informacao_comunicacao","servico_financeiro_seguro","industria_transformacao","infraestrutura_energia","infraestrutura_agua","infraestrutura_residuos_liquidos","infraestrutura_residuos_solidos","infraestrutura_gestao_residuos"]
A13: AUAS | B13: 60 | C13: 2 | E13: 20 | F13: 5 | I13: 50 | J13: ["residencial_unifamiliar","residencial_multifamiliar","comercio_varejista_pequeno","comercio_varejista_medio","comercio_varejista_grande","comercio_atacadista_pequeno","comercio_atacadista_medio_grande","servico_transporte_armazenagem_correio","servico_alojamento_alimentacao","servico_informacao_comunicacao","servico_financeiro_seguro","industria_transformacao","infraestrutura_energia","infraestrutura_agua","infraestrutura_residuos_liquidos","infraestrutura_residuos_solidos","infraestrutura_gestao_residuos"] | L13: ["agricultura","industria_extrativista"]
A14: ARPA | B14: 5 | C14: 0.1 | E14: 80 | F14: 10 | G14: 5 | H14: 5 | J14: ["infraestrutura_energia","infraestrutura_agua","infraestrutura_residuos_liquidos","infraestrutura_residuos_solidos","infraestrutura_gestao_residuos"] | L14: ["residencial_unifamiliar","residencial_multifamiliar","comercio_varejista_pequeno","comercio_varejista_medio","comercio_varejista_grande","comercio_atacadista_pequeno","comercio_atacadista_medio_grande","servico_transporte_armazenagem_correio","servico_alojamento_alimentacao","servico_informacao_comunicacao","servico_financeiro_seguro","industria_transformacao","industria_extrativista","agricultura","producao_florestal","pesca_aquicultura"]
A15: AUAP | B15: 60 | C15: 4 | E15: 20 | F15: 5 | I15: 60 | J15: ["residencial_unifamiliar","residencial_multifamiliar","comercio_varejista_pequeno","comercio_varejista_medio","comercio_varejista_grande","comercio_atacadista_pequeno","comercio_atacadista_medio_grande","servico_transporte_armazenagem_correio","servico_alojamento_alimentacao","servico_informacao_comunicacao","servico_financeiro_seguro","industria_transformacao","infraestrutura_energia","infraestrutura_agua","infraestrutura_residuos_liquidos","infraestrutura_residuos_solidos","infraestrutura_gestao_residuos"] | L15: ["agricultura","industria_extrativista"]
A16: SA-02 | B16: 60 | C16: 3 | D16: 25 | E16: 20 | F16: 5 | I16: 60 | J16: ["residencial_unifamiliar","residencial_multifamiliar","comercio_varejista_pequeno","comercio_varejista_medio","comercio_varejista_grande","comercio_atacadista_pequeno","comercio_atacadista_medio_grande","servico_transporte_armazenagem_correio","servico_alojamento_alimentacao","servico_informacao_comunicacao","servico_financeiro_seguro","industria_transformacao","infraestrutura_energia","infraestrutura_agua","infraestrutura_residuos_liquidos","infraestrutura_residuos_solidos","infraestrutura_gestao_residuos"]
A17: FV | B17: 60 | C17: 2 | D17: 30 | E17: 20 | F17: 5 | I17: 50 | J17: ["residencial_unifamiliar","residencial_multifamiliar","comercio_varejista_pequeno","comercio_varejista_medio","comercio_varejista_grande","comercio_atacadista_pequeno","comercio_atacadista_medio_grande","servico_transporte_armazenagem_correio","servico_alojamento_alimentacao","servico_informacao_comunicacao","servico_financeiro_seguro","industria_transformacao","infraestrutura_energia","infraestrutura_agua","infraestrutura_residuos_liquidos","infraestrutura_residuos_solidos","infraestrutura_gestao_residuos"]
A18: SE-02 | B18: 60 | C18: 2 | D18: 15 | E18: 20 | F18: 5 | I18: 60 | J18: ["residencial_unifamiliar","residencial_multifamiliar","comercio_varejista_pequeno","comercio_varejista_medio","comercio_varejista_grande","comercio_atacadista_pequeno","comercio_atacadista_medio_grande","servico_transporte_armazenagem_correio","servico_alojamento_alimentacao","servico_informacao_comunicacao","servico_financeiro_seguro","industria_transformacao","infraestrutura_energia","infraestrutura_agua","infraestrutura_residuos_liquidos","infraestrutura_residuos_solidos","infraestrutura_gestao_residuos"]
A19: SE-01 | B19: 60 | C19: 4 | D19: 30 | E19: 20 | F19: 5 | I19: 60 | J19: ["residencial_unifamiliar","residencial_multifamiliar","comercio_varejista_pequeno","comercio_varejista_medio","comercio_varejista_grande","comercio_atacadista_pequeno","comercio_atacadista_medio_grande","servico_transporte_armazenagem_correio","servico_alojamento_alimentacao","servico_informacao_comunicacao","servico_financeiro_seguro","industria_transformacao","infraestrutura_energia","infraestrutura_agua","infraestrutura_residuos_liquidos","infraestrutura_residuos_solidos","infraestrutura_gestao_residuos"]
A20: SE-04 | B20: 60 | C20: 0.1 | D20: 9 | E20: 20 | F20: 5 | I20: 50 | J20: ["residencial_unifamiliar","residencial_multifamiliar","comercio_varejista_pequeno","comercio_varejista_medio","comercio_varejista_grande","comercio_atacadista_pequeno","comercio_atacadista_medio_grande","servico_transporte_armazenagem_correio","servico_alojamento_alimentacao","servico_informacao_comunicacao","servico_financeiro_seguro","industria_transformacao","infraestrutura_energia","infraestrutura_agua","infraestrutura_residuos_liquidos","infraestrutura_residuos_solidos","infraestrutura_gestao_residuos"]
A21: AUPA | B21: 10 | C21: 0.1 | E21: 80 | F21: 10 | G21: 5 | H21: 5 | J21: ["infraestrutura_energia","infraestrutura_agua","infraestrutura_residuos_liquidos","infraestrutura_residuos_solidos","infraestrutura_gestao_residuos"] | L21: ["residencial_unifamiliar","residencial_multifamiliar","comercio_varejista_pequeno","comercio_varejista_medio","comercio_varejista_grande","comercio_atacadista_pequeno","comercio_atacadista_medio_grande","servico_transporte_armazenagem_correio","servico_alojamento_alimentacao","servico_informacao_comunicacao","servico_financeiro_seguro","industria_transformacao","industria_extrativista","agricultura","producao_florestal","pesca_aquicultura"]
A22: SE-05 | B22: 60 | C22: 0.1 | D22: 9 | E22: 20 | F22: 5 | I22: 50 | J22: ["residencial_unifamiliar","residencial_multifamiliar","comercio_varejista_pequeno","comercio_varejista_medio","comercio_varejista_grande","comercio_atacadista_pequeno","comercio_atacadista_medio_grande","servico_transporte_armazenagem_correio","servico_alojamento_alimentacao","servico_informacao_comunicacao","servico_financeiro_seguro","industria_transformacao","infraestrutura_energia","infraestrutura_agua","infraestrutura_residuos_liquidos","infraestrutura_residuos_solidos","infraestrutura_gestao_residuos"]
A23: SA-03 | B23: 60 | C23: 2 | D23: 15 | E23: 20 | F23: 5 | I23: 50 | J23: ["residencial_unifamiliar","residencial_multifamiliar","comercio_varejista_pequeno","comercio_varejista_medio","comercio_varejista_grande","comercio_atacadista_pequeno","comercio_atacadista_medio_grande","servico_transporte_armazenagem_correio","servico_alojamento_alimentacao","servico_informacao_comunicacao","servico_financeiro_seguro","industria_transformacao","infraestrutura_energia","infraestrutura_agua","infraestrutura_residuos_liquidos","infraestrutura_residuos_solidos","infraestrutura_gestao_residuos"]
A24: AUAC | B24: 60 | C24: 1.5 | E24: 20 | F24: 5 | I24: 50 | J24: ["residencial_unifamiliar","residencial_multifamiliar","comercio_varejista_pequeno","comercio_varejista_medio","comercio_varejista_grande","comercio_atacadista_pequeno","comercio_atacadista_medio_grande","servico_transporte_armazenagem_correio","servico_alojamento_alimentacao","servico_informacao_comunicacao","servico_financeiro_seguro","industria_transformacao","infraestrutura_energia","infraestrutura_agua","infraestrutura_residuos_liquidos","infraestrutura_residuos_solidos","infraestrutura_gestao_residuos"] | L24: ["agricultura","industria_extrativista"]
A25: ARUC | B25: 10 | C25: 0.1 | E25: 80 | F25: 10 | G25: 5 | H25: 5 | J25: ["residencial_unifamiliar","comercio_varejista_pequeno","comercio_atacadista_pequeno","servico_transporte_armazenagem_correio","servico_alojamento_alimentacao","servico_financeiro_seguro","agricultura_pecuaria","producao_florestal","pesca_aquicultura","industria_extrativista","industria_transformacao","infraestrutura_energia","infraestrutura_agua","infraestrutura_residuos_liquidos","infraestrutura_residuos_solidos","infraestrutura_gestao_residuos"] | L25: ["residencial_multifamiliar"]
A26: SA-01 | B26: 60 | C26: 4 | D26: 45 | E26: 20 | F26: 5 | G26: 1.5 | H26: 1.5 | I26: 120 | J26: [] | K26: [] | L26: []

Sheet Planilha1
A1: macrozona | B1: setor

Sheet Planilha13
A1: subtipo | C1: subtipo
A2: Unifamiliar | C2: Unifamiliar
A3: Multifamiliar | C3: Multifamiliar
A4: Varejista | C4: Varejista
A5: Atacadista | C5: Atacadista
A6: Atividades de Transporte, Armazenagem e Correio (3) (4) | C6: Atividades de Transporte, Armazenagem e Correio (3) (4)
A7: Atividades de Alojamento e Alimentação | C7: Atividades de Alojamento e Alimentação
A8: Atividades de Informação e Comunicação | C8: Atividades de Informação e Comunicação
A9: Atividades Financeiras, de Seguros e Serviços Relacionados | C9: Atividades Financeiras, de Seguros e Serviços Relacionados
A10: Atividades Imobiliárias | C10: Atividades Imobiliárias
A11: Atividades Profissionais Científicas e Técnicas. | C11: Atividades Profissionais Científicas e Técnicas.
A12: Atividades Administrativas(inclusive segurança e educação) e Serviços Complementares | C12: Atividades Administrativas (inclusive segurança e educação) e Serviços Complementares
... A47: Manutenção, Reparação e Instalação de Máquinas e Equipamentos. | C47: Manutenção, Reparação e Instalação de Máquinas e Equipamentos.

Sheet Planilha6
A2: AUAP | B2: SA-01 | C2: SA-02 | D2: SA-03 | E2: SA-04 | F2: SA-05 | G2: SAR | H2: SE-01 | I2: SE-02 | J2: SE-03 | K2: SE-04 | L2: SE-05 | M2: SE-06 | N2: SE-07 | O2: SE-08 | P2: SE-09 | Q2: FV | R2: FR
A3: AUAS | B3: SA-01 | C3: SA-02 | D3: SA-03 | E3: SA-04 | F3: SA-05 | G3: SAR | H3: SE-01 | I3: SE-02 | J3: SE-03 | K3: SE-04 | L3: SE-05 | M3: SE-06 | N3: SE-07 | O3: SE-08 | P3: SE-09 | Q3: FV | R3: FR
A4: AUAC | B4: SA-01 | C4: SA-02 | D4: SA-03 | E4: SA-04 | F4: SA-05 | G4: SAR | H4: SE-01 | I4: SE-02 | J4: SE-03 | K4: SE-04 | L4: SE-05 | M4: SE-06 | N4: SE-07 | O4: SE-08 | P4: SE-09 | Q4: FV | R4: FR
A5: AUAE | B5: SA-01 | C5: SA-02 | D5: SA-03 | E5: SA-04 | F5: SA-05 | G5: SAR | H5: SE-01 | I5: SE-02 | J5: SE-03 | K5: SE-04 | L5: SE-05 | M5: SE-06 | N5: SE-07 | O5: SE-08 | P5: SE-09 | Q5: FV | R5: FR
A6: AUPA | B6: SA-01 | C6: SA-02 | D6: SA-03 | E6: SA-04 | F6: SA-05 | G6: SAR | H6: SE-01 | I6: SE-02 | J6: SE-03 | K6: SE-04 | L6: SE-05 | M6: SE-06 | N6: SE-07 | O6: SE-08 | P6: SE-09 | Q6: FV | R6: FR
A7: ARPA | B7: SA-01 | C7: SA-02 | D7: SA-03 | E7: SA-04 | F7: SA-05 | G7: SAR | H7: SE-01 | I7: SE-02 | J7: SE-03 | K7: SE-04 | L7: SE-05 | M7: SE-06 | N7: SE-07 | O7: SE-08 | P7: SE-09 | Q7: FV | R7: FR
A8: ARUC | B8: SA-01 | C8: SA-02 | D8: SA-03 | E8: SA-04 | F8: SA-05 | G8: SAR | H8: SE-01 | I8: SE-02 | J8: SE-03 | K8: SE-04 | L8: SE-05 | M8: SE-06 | N8: SE-07 | O8: SE-08 | P8: SE-09 | Q8: FV | R8: FR
A11: AUAP | B11: SA-01 | H11: SE-03 | J11: SE-08
A12: AUAS | B12: SA-01 | H12: SE-03 | J12: SE-08
A13: AUAC | B13: SA-01 | H13: SE-03 | J13: SE-08
A14: AUAE | B14: SA-01 | H14: SE-03 | J14: SE-08
A15: AUPA | B15: SA-01 | H15: SE-03 | J15: SE-08
A16: ARPA | B16: SA-01 | H16: SE-03 | J16: SE-08
A17: ARUC | B17: SA-01 | H17: SE-03 | J17: SE-08
A18: AUAP | B18: SA-02 | H18: SE-04 | J18: SE-09
A19: AUAS | B19: SA-02 | H19: SE-04 | J19: SE-09
A20: AUAC | B20: SA-02 | H20: SE-04 | J20: SE-09
A21: AUAE | B21: SA-02 | H21: SE-04 | J21: SE-09
A22: AUPA | B22: SA-02 | H22: SE-04 | J22: SE-09
... A38: ARUC | B38: SA-04 | H38: SE-06 | J38: FR
A39: AUAP | B39: SA-05 | H39: SE-07
A40: AUAS | B40: SA-05 | H40: SE-07
A41: AUAC | B41: SA-05 | H41: SE-07
A42: AUAE | B42: SA-05 | H42: SE-07
A43: AUPA | B43: SA-05 | H43: SE-07
A44: ARPA | B44: SA-05 | H44: SE-07
A45: ARUC | B45: SA-05 | H45: SE-07
A46: AUAP | B46: SAR | H46: SE-08
A47: AUAS | B47: SAR | H47: SE-08
A48: AUAC | B48: SAR | H48: SE-08
A49: AUAE | B49: SAR | H49: SE-08
A50: AUPA | B50: SAR | H50: SE-08
... A73: ARUC | B73: SE-03 | H73: FR
A74: AUAP | B74: SE-04
A75: AUAS | B75: SE-04
A76: AUAC | B76: SE-04
A77: AUAE | B77: SE-04
A78: AUPA | B78: SE-04
A79: ARPA | B79: SE-04
A80: ARUC | B80: SE-04
...

Sheet MACROZONAS
A1: macrozona_id | B1: macrozona | C1: tipo | D1: codigo | E1: descricao | F1: observacoes | G1: obs_tabela
A2: 1 | B2: AUAP | C2: Macrozona Urbana | D2: 1 | E2: Área Urbana de Adensamento Prioritário | F2: 1 | G2: parametros
A3: 2 | B3: AUAS | C3: Macrozona Urbana | D3: 2 | E3: Área Urbana de Adensamento Secundário | G3: parametros
A4: 3 | B4: AUAC | C4: Macrozona Urbana | D4: 3 | E4: Área Urbana de Adensamento Controlado | G4: parametros
A5: 4 | B5: AUAE | C5: Macrozona Urbana | D5: 4 | E5: Área Urbana de Adensamento Especial | G5: parametros
A6: 5 | B6: AUPA | C6: Macrozona Urbana | D6: 5 | E6: Área Urbana de Proteção Ambiental | F6: 9 | G6: parametros
A7: 6 | B7: ARPA | C7: Macrozona Rural | D7: 6 | E7: Área Rural de Proteção Natural | F7: 19 | G7: parametros
A8: 7 | B8: ARUC | C8: Macrozona Rural | D8: 7 | E8: Área Rural de Utilização Controlada | F8: 19 | G8: parametros

Sheet SETORES
A1: setor_id | B1: setor | C1: descricao | D1: obs_tabela
A2: 1 | B2: SA-01 | C2: Setor de Adensamento Prioritário 01 | D2: parametros
A3: 2 | B3: SA-02 | C3: Setor de Adensamento Prioritário 02 | D3: parametros
A4: 3 | B4: SA-03 | C4: Demais setores de Adensamento 03 | D4: parametros
A5: 4 | B5: SA-04 | C5: Demais setores de Adensamento 04 | D5: parametros
A6: 5 | B6: SA-05 | C6: Demais setores de Adensamento 05 | D6: parametros
A7: 6 | B7: SAR | C7: Setor de Adensamento Rural | D7: parametros
A8: 7 | B8: SE-01 | C8: Setor Especial 01 | D8: parametros
A9: 8 | B9: SE-02 | C9: Setor Especial 02 | D9: parametros
A10: 9 | B10: SE-03 | C10: Setor Especial 03 | D10: parametros
A11: 10 | B11: SE-04 | C11: Setor Especial 04 | D11: parametros
A12: 11 | B12: SE-05 | C12: Setor Especial 05 | D12: parametros
A13: 12 | B13: SE-06 | C13: Setor Especial 06 | D13: parametros
... A18: 17 | B18: FR | C18: Faixa Rodoviária | D18: parametros

Sheet CAL
A1: macrozona | B1: setor | C1: cal | D1: obs_setor | E1: obs_coef | F1: obs_geral | G1: obs_tabela | H1: cal_id | I1: cal_macrozona_id | J1: cal_setor_id
A2: AUAP | B2: SA-01 | C2: 4 | E2: 1 | G2: parametros | H2: 1 | I2: {=XLOOKUP(CAL!$A2,MACROZONAS!B:B,MACROZONAS!A:A)} -> 1 | J2: {=XLOOKUP(CAL!$B2,SETORES!B:B,SETORES!A:A)} -> 1
A3: AUAP | B3: SA-02 | C3: 3 | E3: 1 | G3: parametros | H3: 2 | I3: {=XLOOKUP(CAL!$A3,MACROZONAS!B:B,MACROZONAS!A:A)} -> 1 | J3: {=XLOOKUP(CAL!$B3,SETORES!B:B,SETORES!A:A)} -> 2
A4: AUAP | B4: SE-01 | C4: 4 | E4: 3 | G4: parametros | H4: 3 | I4: {=XLOOKUP(CAL!$A4,MACROZONAS!B:B,MACROZONAS!A:A)} -> 1 | J4: {=XLOOKUP(CAL!$B4,SETORES!B:B,SETORES!A:A)} -> 7
A5: AUAP | B5: SE-02 | C5: 2 | E5: 1 | G5: parametros | H5: 4 | I5: {=XLOOKUP(CAL!$A5,MACROZONAS!B:B,MACROZONAS!A:A)} -> 1 | J5: {=XLOOKUP(CAL!$B5,SETORES!B:B,SETORES!A:A)} -> 8
A6: AUAP | B6: SE-04 | C6: 0.1 | D6: 10 | G6: parametros | H6: 5 | I6: {=XLOOKUP(CAL!$A6,MACROZONAS!B:B,MACROZONAS!A:A)} -> 1 | J6: {=XLOOKUP(CAL!$B6,SETORES!B:B,SETORES!A:A)} -> 10
A7: AUAP | B7: SE-05 | C7: 0.1 | D7: 10 | G7: parametros | H7: 6 | I7: {=XLOOKUP(CAL!$A7,MACROZONAS!B:B,MACROZONAS!A:A)} -> 1 | J7: {=XLOOKUP(CAL!$B7,SETORES!B:B,SETORES!A:A)} -> 11
A8: AUAP | B8: SE-08 | C8: 4 | D8: 1 | E8: 1 | G8: parametros | H8: 7 | I8: {=XLOOKUP(CAL!$A8,MACROZONAS!B:B,MACROZONAS!A:A)} -> 1 | J8: {=XLOOKUP(CAL!$B8,SETORES!B:B,SETORES!A:A)} -> 14
A9: AUAP | B9: FV | C9: 4 | E9: 1 | G9: parametros | H9: 8 | I9: {=XLOOKUP(CAL!$A9,MACROZONAS!B:B,MACROZONAS!A:A)} -> 1 | J9: {=XLOOKUP(CAL!$B9,SETORES!B:B,SETORES!A:A)} -> 16
A10: AUAP | B10: FR | C10: 2 | G10: parametros | H10: 9 | I10: {=XLOOKUP(CAL!$A10,MACROZONAS!B:B,MACROZONAS!A:A)} -> 1 | J10: {=XLOOKUP(CAL!$B10,SETORES!B:B,SETORES!A:A)} -> 17
A11: AUAS | B11: SA-03 | C11: 2 | G11: parametros | H11: 10 | I11: {=XLOOKUP(CAL!$A11,MACROZONAS!B:B,MACROZONAS!A:A)} -> 2 | J11: {=XLOOKUP(CAL!$B11,SETORES!B:B,SETORES!A:A)} -> 3
A12: AUAS | B12: SA-04 | C12: 2 | G12: parametros | H12: 11 | I12: {=XLOOKUP(CAL!$A12,MACROZONAS!B:B,MACROZONAS!A:A)} -> 2 | J12: {=XLOOKUP(CAL!$B12,SETORES!B:B,SETORES!A:A)} -> 4
A13: AUAS | B13: SA-05 | C13: 2 | G13: parametros | H13: 12 | I13: {=XLOOKUP(CAL!$A13,MACROZONAS!B:B,MACROZONAS!A:A)} -> 2 | J13: {=XLOOKUP(CAL!$B13,SETORES!B:B,SETORES!A:A)} -> 5
A14: AUAS | B14: SAR | C14: 2 | G14: parametros | H14: 13 | I14: {=XLOOKUP(CAL!$A14,MACROZONAS!B:B,MACROZONAS!A:A)} -> 2 | J14: {=XLOOKUP(CAL!$B14,SETORES!B:B,SETORES!A:A)} -> 6
A15: AUAS | B15: SE-03 | C15: 1 | G15: parametros | H15: 14 | I15: {=XLOOKUP(CAL!$A15,MACROZONAS!B:B,MACROZONAS!A:A)} -> 2 | J15: {=XLOOKUP(CAL!$B15,SETORES!B:B,SETORES!A:A)} -> 9
A16: AUAS | B16: SE-04 | C16: 0.1 | D16: 10 | G16: parametros | H16: 15 | I16: {=XLOOKUP(CAL!$A16,MACROZONAS!B:B,MACROZONAS!A:A)} -> 2 | J16: {=XLOOKUP(CAL!$B16,SETORES!B:B,SETORES!A:A)} -> 10
A17: AUAS | B17: SE-05 | C17: 0.1 | D17: 10 | G17: parametros | H17: 16 | I17: {=XLOOKUP(CAL!$A17,MACROZONAS!B:B,MACROZONAS!A:A)} -> 2 | J17: {=XLOOKUP(CAL!$B17,SETORES!B:B,SETORES!A:A)} -> 11
A18: AUAS | B18: SE-08 | C18: 2 | D18: 1 | G18: parametros | H18: 17 | I18: {=XLOOKUP(CAL!$A18,MACROZONAS!B:B,MACROZONAS!A:A)} -> 2 | J18: {=XLOOKUP(CAL!$B18,SETORES!B:B,SETORES!A:A)} -> 14
A19: AUAS | B19: SE-09 | C19: 2 | G19: parametros | H19: 18 | I19: {=XLOOKUP(CAL!$A19,MACROZONAS!B:B,MACROZONAS!A:A)} -> 2 | J19: {=XLOOKUP(CAL!$B19,SETORES!B:B,SETORES!A:A)} -> 15
A20: AUAS | B20: FV | C20: 2 | E20: 1 | G20: parametros | H20: 19 | I20: {=XLOOKUP(CAL!$A20,MACROZONAS!B:B,MACROZONAS!A:A)} -> 2 | J20: {=XLOOKUP(CAL!$B20,SETORES!B:B,SETORES!A:A)} -> 16
A21: AUAS | B21: FR | C21: 1 | G21: parametros | H21: 20 | I21: {=XLOOKUP(CAL!$A21,MACROZONAS!B:B,MACROZONAS!A:A)} -> 2 | J21: {=XLOOKUP(CAL!$B21,SETORES!B:B,SETORES!A:A)} -> 17
A22: AUAC | B22: SA-03 | C22: 1.5 | G22: parametros | H22: 21 | I22: {=XLOOKUP(CAL!$A22,MACROZONAS!B:B,MACROZONAS!A:A)} -> 3 | J22: {=XLOOKUP(CAL!$B22,SETORES!B:B,SETORES!A:A)} -> 3
A23: AUAC | B23: SA-04 | C23: 1.5 | G23: parametros | H23: 22 | I23: {=XLOOKUP(CAL!$A23,MACROZONAS!B:B,MACROZONAS!A:A)} -> 3 | J23: {=XLOOKUP(CAL!$B23,SETORES!B:B,SETORES!A:A)} -> 4
A24: AUAC | B24: SA-05 | C24: 1.5 | G24: parametros | H24: 23 | I24: {=XLOOKUP(CAL!$A24,MACROZONAS!B:B,MACROZONAS!A:A)} -> 3 | J24: {=XLOOKUP(CAL!$B24,SETORES!B:B,SETORES!A:A)} -> 5
A25: AUAC | B25: SAR | C25: 1.5 | G25: parametros | H25: 24 | I25: {=XLOOKUP(CAL!$A25,MACROZONAS!B:B,MACROZONAS!A:A)} -> 3 | J25: {=XLOOKUP(CAL!$B25,SETORES!B:B,SETORES!A:A)} -> 6
A26: AUAC | B26: SE-04 | C26: 0.1 | D26: 10 | G26: parametros | H26: 25 | I26: {=XLOOKUP(CAL!$A26,MACROZONAS!B:B,MACROZONAS!A:A)} -> 3 | J26: {=XLOOKUP(CAL!$B26,SETORES!B:B,SETORES!A:A)} -> 10
A27: AUAC | B27: SE-05 | C27: 0.1 | D27: 10 | G27: parametros | H27: 26 | I27: {=XLOOKUP(CAL!$A27,MACROZONAS!B:B,MACROZONAS!A:A)} -> 3 | J27: {=XLOOKUP(CAL!$B27,SETORES!B:B,SETORES!A:A)} -> 11
A28: AUAC | B28: SE-06 | C28: 1 | G28: parametros | H28: 27 | I28: {=XLOOKUP(CAL!$A28,MACROZONAS!B:B,MACROZONAS!A:A)} -> 3 | J28: {=XLOOKUP(CAL!$B28,SETORES!B:B,SETORES!A:A)} -> 12
A29: AUAC | B29: SE-08 | C29: 1 | D29: 1 | G29: parametros | H29: 28 | I29: {=XLOOKUP(CAL!$A29,MACROZONAS!B:B,MACROZONAS!A:A)} -> 3 | J29: {=XLOOKUP(CAL!$B29,SETORES!B:B,SETORES!A:A)} -> 14
A30: AUAC | B30: FV | C30: 1.5 | E30: 1 | G30: parametros | H30: 29 | I30: {=XLOOKUP(CAL!$A30,MACROZONAS!B:B,MACROZONAS!A:A)} -> 3 | J30: {=XLOOKUP(CAL!$B30,SETORES!B:B,SETORES!A:A)} -> 16
A31: AUAC | B31: FR | C31: 1 | G31: parametros | H31: 30 | I31: {=XLOOKUP(CAL!$A31,MACROZONAS!B:B,MACROZONAS!A:A)} -> 3 | J31: {=XLOOKUP(CAL!$B31,SETORES!B:B,SETORES!A:A)} -> 17
A32: AUAE | B32: SA-03 | C32: 1 | G32: parametros | H32: 31 | I32: {=XLOOKUP(CAL!$A32,MACROZONAS!B:B,MACROZONAS!A:A)} -> 4 | J32: {=XLOOKUP(CAL!$B32,SETORES!B:B,SETORES!A:A)} -> 3
A33: AUAE | B33: SA-04 | C33: 1 | G33: parametros | H33: 32 | I33: {=XLOOKUP(CAL!$A33,MACROZONAS!B:B,MACROZONAS!A:A)} -> 4 | J33: {=XLOOKUP(CAL!$B33,SETORES!B:B,SETORES!A:A)} -> 4
A34: AUAE | B34: SA-05 | C34: 1 | G34: parametros | H34: 33 | I34: {=XLOOKUP(CAL!$A34,MACROZONAS!B:B,MACROZONAS!A:A)} -> 4 | J34: {=XLOOKUP(CAL!$B34,SETORES!B:B,SETORES!A:A)} -> 5
A35: AUAE | B35: SAR | C35: 1 | G35: parametros | H35: 34 | I35: {=XLOOKUP(CAL!$A35,MACROZONAS!B:B,MACROZONAS!A:A)} -> 4 | J35: {=XLOOKUP(CAL!$B35,SETORES!B:B,SETORES!A:A)} -> 6
A36: AUAE | B36: SE-04 | C36: 0.1 | D36: 10 | G36: parametros | H36: 35 | I36: {=XLOOKUP(CAL!$A36,MACROZONAS!B:B,MACROZONAS!A:A)} -> 4 | J36: {=XLOOKUP(CAL!$B36,SETORES!B:B,SETORES!A:A)} -> 10
A37: AUAE | B37: SE-05 | C37: 0.1 | D37: 10 | G37: parametros | H37: 36 | I37: {=XLOOKUP(CAL!$A37,MACROZONAS!B:B,MACROZONAS!A:A)} -> 4 | J37: {=XLOOKUP(CAL!$B37,SETORES!B:B,SETORES!A:A)} -> 11
A38: AUAE | B38: FV | C38: 4 | E38: 1 | G38: parametros | H38: 37 | I38: {=XLOOKUP(CAL!$A38,MACROZONAS!B:B,MACROZONAS!A:A)} -> 4 | J38: {=XLOOKUP(CAL!$B38,SETORES!B:B,SETORES!A:A)} -> 16
A39: AUPA | B39: SA-03 | C39: 0.1 | G39: parametros | H39: 38 | I39: {=XLOOKUP(CAL!$A39,MACROZONAS!B:B,MACROZONAS!A:A)} -> 5 | J39: {=XLOOKUP(CAL!$B39,SETORES!B:B,SETORES!A:A)} -> 3
A40: AUPA | B40: SA-04 | C40: 0.1 | G40: parametros | H40: 39 | I40: {=XLOOKUP(CAL!$A40,MACROZONAS!B:B,MACROZONAS!A:A)} -> 5 | J40: {=XLOOKUP(CAL!$B40,SETORES!B:B,SETORES!A:A)} -> 4
...

Sheet GABARITO
A1: macrozona | B1: setor | C1: gabarito | D1: obs_setor | E1: obs_coef | F1: obs_geral | G1: obs_tabela | H1: gab_id | I1: gab_macrozona_id | J1: gab_setor_id
A2: AUAP | B2: SA-01 | C2: 45 | D2: 17 | F2: 14 | G2: parametros | H2: 1 | I2: {=XLOOKUP(GABARITO!$A2,MACROZONAS!B:B,MACROZONAS!A:A)} -> 1 | J2: {=XLOOKUP(GABARITO!$B2,SETORES!B:B,SETORES!A:A)} -> 1
A3: AUAP | B3: SA-02 | C3: 24 | D3: 17 | F3: 14 | G3: parametros | H3: 2 | I3: {=XLOOKUP(GABARITO!$A3,MACROZONAS!B:B,MACROZONAS!A:A)} -> 1 | J3: {=XLOOKUP(GABARITO!$B3,SETORES!B:B,SETORES!A:A)} -> 2
A4: AUAS | B4: SA-03 | C4: 15 | F4: 14 | G4: parametros | H4: 3 | I4: {=XLOOKUP(GABARITO!$A4,MACROZONAS!B:B,MACROZONAS!A:A)} -> 2 | J4: {=XLOOKUP(GABARITO!$B4,SETORES!B:B,SETORES!A:A)} -> 3
A5: AUAS | B5: SA-04 | C5: 15 | F5: 14 | G5: parametros | H5: 4 | I5: {=XLOOKUP(GABARITO!$A5,MACROZONAS!B:B,MACROZONAS!A:A)} -> 2 | J5: {=XLOOKUP(GABARITO!$B5,SETORES!B:B,SETORES!A:A)} -> 4
A6: AUAS | B6: SA-05 | C6: 15 | F6: 14 | G6: parametros | H6: 5 | I6: {=XLOOKUP(GABARITO!$A6,MACROZONAS!B:B,MACROZONAS!A:A)} -> 2 | J6: {=XLOOKUP(GABARITO!$B6,SETORES!B:B,SETORES!A:A)} -> 5
A7: AUAS | B7: SAR | C7: 15 | F7: 14 | G7: parametros | H7: 6 | I7: {=XLOOKUP(GABARITO!$A7,MACROZONAS!B:B,MACROZONAS!A:A)} -> 2 | J7: {=XLOOKUP(GABARITO!$B7,SETORES!B:B,SETORES!A:A)} -> 6
A8: AUAC | B8: SA-03 | C8: 9 | F8: 14 | G8: parametros | H8: 7 | I8: {=XLOOKUP(GABARITO!$A8,MACROZONAS!B:B,MACROZONAS!A:A)} -> 3 | J8: {=XLOOKUP(GABARITO!$B8,SETORES!B:B,SETORES!A:A)} -> 3
A9: AUAC | B9: SA-04 | C9: 9 | F9: 14 | G9: parametros | H9: 8 | I9: {=XLOOKUP(GABARITO!$A9,MACROZONAS!B:B,MACROZONAS!A:A)} -> 3 | J9: {=XLOOKUP(GABARITO!$B9,SETORES!B:B,SETORES!A:A)} -> 4
A10: AUAC | B10: SA-05 | C10: 9 | F10: 14 | G10: parametros | H10: 9 | I10: {=XLOOKUP(GABARITO!$A10,MACROZONAS!B:B,MACROZONAS!A:A)} -> 3 | J10: {=XLOOKUP(GABARITO!$B10,SETORES!B:B,SETORES!A:A)} -> 5
A11: AUAC | B11: SAR | C11: 9 | F11: 14 | G11: parametros | H11: 10 | I11: {=XLOOKUP(GABARITO!$A11,MACROZONAS!B:B,MACROZONAS!A:A)} -> 3 | J11: {=XLOOKUP(GABARITO!$B11,SETORES!B:B,SETORES!A:A)} -> 6
A12: AUAE | B12: SA-03 | C12: 9 | F12: 14 | G12: parametros | H12: 11 | I12: {=XLOOKUP(GABARITO!$A12,MACROZONAS!B:B,MACROZONAS!A:A)} -> 4 | J12: {=XLOOKUP(GABARITO!$B12,SETORES!B:B,SETORES!A:A)} -> 3
A13: AUAE | B13: SA-04 | C13: 9 | F13: 14 | G13: parametros | H13: 12 | I13: {=XLOOKUP(GABARITO!$A13,MACROZONAS!B:B,MACROZONAS!A:A)} -> 4 | J13: {=XLOOKUP(GABARITO!$B13,SETORES!B:B,SETORES!A:A)} -> 4
A14: AUAE | B14: SA-05 | C14: 9 | F14: 14 | G14: parametros | H14: 13 | I14: {=XLOOKUP(GABARITO!$A14,MACROZONAS!B:B,MACROZONAS!A:A)} -> 4 | J14: {=XLOOKUP(GABARITO!$B14,SETORES!B:B,SETORES!A:A)} -> 5
A15: AUAE | B15: SAR | C15: 9 | F15: 14 | G15: parametros | H15: 14 | I15: {=XLOOKUP(GABARITO!$A15,MACROZONAS!B:B,MACROZONAS!A:A)} -> 4 | J15: {=XLOOKUP(GABARITO!$B15,SETORES!B:B,SETORES!A:A)} -> 6
... A27: ARUC | B27: SAR | C27: 9 | F27: 14 | G27: parametros | H27: 26 | I27: {=XLOOKUP(GABARITO!$A27,MACROZONAS!B:B,MACROZONAS!A:A)} -> 7 | J27: {=XLOOKUP(GABARITO!$B27,SETORES!B:B,SETORES!A:A)} -> 6
A28: AUAP | B28: SE-01 | C28: 30 | D28: 17 | E28: 3 | F28: 14 | G28: parametros | H28: 27 | I28: {=XLOOKUP(GABARITO!$A28,MACROZONAS!B:B,MACROZONAS!A:A)} -> 1 | J28: {=XLOOKUP(GABARITO!$B28,SETORES!B:B,SETORES!A:A)} -> 7
A29: AUAP | B29: SA-02 | C29: 15 | D29: 17 | F29: 14 | G29: parametros | H29: 28 | I29: {=XLOOKUP(GABARITO!$A29,MACROZONAS!B:B,MACROZONAS!A:A)} -> 1 | J29: {=XLOOKUP(GABARITO!$B29,SETORES!B:B,SETORES!A:A)} -> 2
A30: AUAS | B30: SE-03 | C30: 30 | F30: 14 | G30: parametros | H30: 29 | I30: {=XLOOKUP(GABARITO!$A30,MACROZONAS!B:B,MACROZONAS!A:A)} -> 2 | J30: {=XLOOKUP(GABARITO!$B30,SETORES!B:B,SETORES!A:A)} -> 9
A31: AUAP | B31: SE-04 | C31: 9 | D31: 10 | F31: 14 | G31: parametros | H31: 30 | I31: {=XLOOKUP(GABARITO!$A31,MACROZONAS!B:B,MACROZONAS!A:A)} -> 1 | J31: {=XLOOKUP(GABARITO!$B31,SETORES!B:B,SETORES!A:A)} -> 10
A32: AUAS | B32: SE-04 | C32: 9 | D32: 10 | F32: 14 | G32: parametros | H32: 31 | I32: {=XLOOKUP(GABARITO!$A32,MACROZONAS!B:B,MACROZONAS!A:A)} -> 2 | J32: {=XLOOKUP(GABARITO!$B32,SETORES!B:B,SETORES!A:A)} -> 10
A33: AUAC | B33: SE-04 | C33: 9 | D33: 10 | F33: 14 | G33: parametros | H33: 32 | I33: {=XLOOKUP(GABARITO!$A33,MACROZONAS!B:B,MACROZONAS!A:A)} -> 3 | J33: {=XLOOKUP(GABARITO!$B33,SETORES!B:B,SETORES!A:A)} -> 10
A34: AUAE | B34: SE-04 | C34: 9 | D34: 10 | F34: 14 | G34: parametros | H34: 33 | I34: {=XLOOKUP(GABARITO!$A34,MACROZONAS!B:B,MACROZONAS!A:A)} -> 4 | J34: {=XLOOKUP(GABARITO!$B34,SETORES!B:B,SETORES!A:A)} -> 10
A35: AUPA | B35: SE-04 | C35: 9 | D35: 10 | F35: 14 | G35: parametros | H35: 34 | I35: {=XLOOKUP(GABARITO!$A35,MACROZONAS!B:B,MACROZONAS!A:A)} -> 5 | J35: {=XLOOKUP(GABARITO!$B35,SETORES!B:B,SETORES!A:A)} -> 10
A36: AUAP | B36: SE-05 | C36: 9 | D36: 10 | F36: 14 | G36: parametros | H36: 35 | I36: {=XLOOKUP(GABARITO!$A36,MACROZONAS!B:B,MACROZONAS!A:A)} -> 1 | J36: {=XLOOKUP(GABARITO!$B36,SETORES!B:B,SETORES!A:A)} -> 11
A37: AUAS | B37: SE-05 | C37: 9 | D37: 10 | F37: 14 | G37: parametros | H37: 36 | I37: {=XLOOKUP(GABARITO!$A37,MACROZONAS!B:B,MACROZONAS!A:A)} -> 2 | J37: {=XLOOKUP(GABARITO!$B37,SETORES!B:B,SETORES!A:A)} -> 11
A38: AUAC | B38: SE-05 | C38: 9 | D38: 10 | F38: 14 | G38: parametros | H38: 37 | I38: {=XLOOKUP(GABARITO!$A38,MACROZONAS!B:B,MACROZONAS!A:A)} -> 3 | J38: {=XLOOKUP(GABARITO!$B38,SETORES!B:B,SETORES!A:A)} -> 11
A39: AUAE | B39: SE-05 | C39: 9 | D39: 10 | F39: 14 | G39: parametros | H39: 38 | I39: {=XLOOKUP(GABARITO!$A39,MACROZONAS!B:B,MACROZONAS!A:A)} -> 4 | J39: {=XLOOKUP(GABARITO!$B39,SETORES!B:B,SETORES!A:A)} -> 11
A40: AUPA | B40: SE-05 | C40: 9 | D40: 10 | F40: 14 | G40: parametros | H40: 39 | I40: {=XLOOKUP(GABARITO!$A40,MACROZONAS!B:B,MACROZONAS!A:A)} -> 5 | J40: {=XLOOKUP(GABARITO!$B40,SETORES!B:B,SETORES!A:A)} -> 11
A41: AUAC | B41: SE-06 | C41: 15 | D41: 13 | F41: 14 | G41: parametros | H41: 40 | I41: {=XLOOKUP(GABARITO!$A41,MACROZONAS!B:B,MACROZONAS!A:A)} -> 3 | J41: {=XLOOKUP(GABARITO!$B41,SETORES!B:B,SETORES!A:A)} -> 12
A42: AUAP | B42: SE-08 | C42: 30 | D42: 17 | E42: 5 | F42: 14 | G42: parametros | H42: 41 | I42: {=XLOOKUP(GABARITO!$A42,MACROZONAS!B:B,MACROZONAS!A:A)} -> 1 | J42: {=XLOOKUP(GABARITO!$B42,SETORES!B:B,SETORES!A:A)} -> 14
A43: AUAS | B43: SE-08 | C43: 15 | D43: 17 | F43: 14 | G43: parametros | H43: 42 | I43: {=XLOOKUP(GABARITO!$A43,MACROZONAS!B:B,MACROZONAS!A:A)} -> 2 | J43: {=XLOOKUP(GABARITO!$B43,SETORES!B:B,SETORES!A:A)} -> 14
A44: AUAC | B44: SE-08 | C44: 9 | D44: 17 | F44: 14 | G44: parametros | H44: 43 | I44: {=XLOOKUP(GABARITO!$A44,MACROZONAS!B:B,MACROZONAS!A:A)} -> 3 | J44: {=XLOOKUP(GABARITO!$B44,SETORES!B:B,SETORES!A:A)} -> 14
A45: AUAP | B45: SE-08 | C45: 45 | D45: 17 | E45: 5 | F45: 14 | G45: parametros | H45: 44 | I45: {=XLOOKUP(GABARITO!$A45,MACROZONAS!B:B,MACROZONAS!A:A)} -> 1 | J45: {=XLOOKUP(GABARITO!$B45,SETORES!B:B,SETORES!A:A)} -> 14
A46: AUAS | B46: SE-09 | C46: 15 | D46: 14 | F46: 14 | G46: parametros | H46: 45 | I46: {=XLOOKUP(GABARITO!$A46,MACROZONAS!B:B,MACROZONAS!A:A)} -> 2 | J46: {=XLOOKUP(GABARITO!$B46,SETORES!B:B,SETORES!A:A)} -> 15
A47: AUAP | B47: FV | C47: 30 | D47: 17 | E47: 5 | F47: 14 | G47: parametros | H47: 46 | I47: {=XLOOKUP(GABARITO!$A47,MACROZONAS!B:B,MACROZONAS!A:A)} -> 1 | J47: {=XLOOKUP(GABARITO!$B47,SETORES!B:B,SETORES!A:A)} -> 16
A48: AUAS | B48: FV | C48: 20 | F48: 14 | G48: parametros | H48: 47 | I48: {=XLOOKUP(GABARITO!$A48,MACROZONAS!B:B,MACROZONAS!A:A)} -> 2 | J48: {=XLOOKUP(GABARITO!$B48,SETORES!B:B,SETORES!A:A)} -> 16
A49: AUAC | B49: FV | C49: 9 | F49: 14 | G49: parametros | H49: 48 | I49: {=XLOOKUP(GABARITO!$A49,MACROZONAS!B:B,MACROZONAS!A:A)} -> 3 | J49: {=XLOOKUP(GABARITO!$B49,SETORES!B:B,SETORES!A:A)} -> 16
A50: AUAE | B50: FV | C50: 30 | F50: 14 | G50: parametros | H50: 49 | I50: {=XLOOKUP(GABARITO!$A50,MACROZONAS!B:B,MACROZONAS!A:A)} -> 4 | J50: {=XLOOKUP(GABARITO!$B50,SETORES!B:B,SETORES!A:A)} -> 16
A51: AUAP | B51: FR | C51: 15 | F51: 14 | G51: parametros | H51: 50 | I51: {=XLOOKUP(GABARITO!$A51,MACROZONAS!B:B,MACROZONAS!A:A)} -> 1 | J51: {=XLOOKUP(GABARITO!$B51,SETORES!B:B,SETORES!A:A)} -> 17
...

Sheet Q.A
A1: macrozona | B1: setor | C1: quota | D1: obs_setor | E1: obs_coef | F1: obs_geral | G1: obs_tabela | H1: quota_id | I1: quota_macrozona_id | J1: quota_setor_id
A2: AUAP | B2: SA-01 | C2: 60 | E2: 2 | G2: parametros | H2: 1 | I2: {=XLOOKUP(Q.A!$A2,MACROZONAS!B:B,MACROZONAS!A:A)} -> 1 | J2: {=XLOOKUP(Q.A!$B2,SETORES!B:B,SETORES!A:A)} -> 1
A3: AUAP | B3: SA-02 | C3: 60 | E3: 2 | G3: parametros | H3: 2 | I3: {=XLOOKUP(Q.A!$A3,MACROZONAS!B:B,MACROZONAS!A:A)} -> 1 | J3: {=XLOOKUP(Q.A!$B3,SETORES!B:B,SETORES!A:A)} -> 2
A4: AUAP | B4: SA-03 | C4: 60 | E4: 2 | G4: parametros | H4: 3 | I4: {=XLOOKUP(Q.A!$A4,MACROZONAS!B:B,MACROZONAS!A:A)} -> 1 | J4: {=XLOOKUP(Q.A!$B4,SETORES!B:B,SETORES!A:A)} -> 3
A5: AUAP | B5: SA-04 | C5: 60 | E5: 2 | G5: parametros | H5: 4 | I5: {=XLOOKUP(Q.A!$A5,MACROZONAS!B:B,MACROZONAS!A:A)} -> 1 | J5: {=XLOOKUP(Q.A!$B5,SETORES!B:B,SETORES!A:A)} -> 4
A6: AUAP | B6: SA-05 | C6: 60 | E6: 2 | G6: parametros | H6: 5 | I6: {=XLOOKUP(Q.A!$A6,MACROZONAS!B:B,MACROZONAS!A:A)} -> 1 | J6: {=XLOOKUP(Q.A!$B6,SETORES!B:B,SETORES!A:A)} -> 5
A7: AUAP | B7: SAR | C7: 60 | E7: 2 | G7: parametros | H7: 6 | I7: {=XLOOKUP(Q.A!$A7,MACROZONAS!B:B,MACROZONAS!A:A)} -> 1 | J7: {=XLOOKUP(Q.A!$B7,SETORES!B:B,SETORES!A:A)} -> 6
A8: AUAP | B8: SE-01 | C8: 60 | E8: 2 | G8: parametros | H8: 7 | I8: {=XLOOKUP(Q.A!$A8,MACROZONAS!B:B,MACROZONAS!A:A)} -> 1 | J8: {=XLOOKUP(Q.A!$B8,SETORES!B:B,SETORES!A:A)} -> 7
A9: AUAP | B9: SE-02 | C9: 60 | E9: 2 | G9: parametros | H9: 8 | I9: {=XLOOKUP(Q.A!$A9,MACROZONAS!B:B,MACROZONAS!A:A)} -> 1 | J9: {=XLOOKUP(Q.A!$B9,SETORES!B:B,SETORES!A:A)} -> 8
A10: AUAP | B10: SE-03 | C10: 60 | E10: 2 | G10: parametros | H10: 9 | I10: {=XLOOKUP(Q.A!$A10,MACROZONAS!B:B,MACROZONAS!A:A)} -> 1 | J10: {=XLOOKUP(Q.A!$B10,SETORES!B:B,SETORES!A:A)} -> 9
A11: AUAP | B11: SE-04 | C11: 60 | E11: 2 | G11: parametros | H11: 10 | I11: {=XLOOKUP(Q.A!$A11,MACROZONAS!B:B,MACROZONAS!A:A)} -> 1 | J11: {=XLOOKUP(Q.A!$B11,SETORES!B:B,SETORES!A:A)} -> 10
A12: AUAP | B12: SE-05 | C12: 60 | E12: 2 | G12: parametros | H12: 11 | I12: {=XLOOKUP(Q.A!$A12,MACROZONAS!B:B,MACROZONAS!A:A)} -> 1 | J12: {=XLOOKUP(Q.A!$B12,SETORES!B:B,SETORES!A:A)} -> 11
A13: AUAP | B13: SE-06 | C13: 60 | E13: 2 | G13: parametros | H13: 12 | I13: {=XLOOKUP(Q.A!$A13,MACROZONAS!B:B,MACROZONAS!A:A)} -> 1 | J13: {=XLOOKUP(Q.A!$B13,SETORES!B:B,SETORES!A:A)} -> 12
... A69: AUAE | B69: FR | C69: 60 | E69: 2 | G69: parametros | H69: 68 | I69: {=XLOOKUP(Q.A!$A69,MACROZONAS!B:B,MACROZONAS!A:A)} -> 4 | J69: {=XLOOKUP(Q.A!$B69,SETORES!B:B,SETORES!A:A)} -> 17

Sheet TO
A1: macrozona | B1: setor | C1: TO | D1: obs_setor | E1: obs_coef | F1: obs_geral | G1: obs_tabela | H1: ocupacao_id | I1: ocupacao_macrozona_id | J1: ocupacao_setor_id
A2: AUAP | B2: SA-01 | C2: 60 | E2: 10 | G2: parametros | H2: 1 | I2: {=XLOOKUP(TO!$A2,MACROZONAS!B:B,MACROZONAS!A:A)} -> 1 | J2: {=XLOOKUP(TO!$B2,SETORES!B:B,SETORES!A:A)} -> 1
A3: AUAS | B3: SA-01 | C3: 60 | E3: 10 | G3: parametros | H3: 2 | I3: {=XLOOKUP(TO!$A3,MACROZONAS!B:B,MACROZONAS!A:A)} -> 2 | J3: {=XLOOKUP(TO!$B3,SETORES!B:B,SETORES!A:A)} -> 1
A4: AUAC | B4: SA-01 | C4: 60 | E4: 10 | G4: parametros | H4: 3 | I4: {=XLOOKUP(TO!$A4,MACROZONAS!B:B,MACROZONAS!A:A)} -> 3 | J4: {=XLOOKUP(TO!$B4,SETORES!B:B,SETORES!A:A)} -> 1
A5: AUAE | B5: SA-01 | C5: 60 | E5: 10 | G5: parametros | H5: 4 | I5: {=XLOOKUP(TO!$A5,MACROZONAS!B:B,MACROZONAS!A:A)} -> 4 | J5: {=XLOOKUP(TO!$B5,SETORES!B:B,SETORES!A:A)} -> 1
A6: AUPA | B6: SA-01 | C6: 10 | E6: 10 | G6: parametros | H6: 5 | I6: {=XLOOKUP(TO!$A6,MACROZONAS!B:B,MACROZONAS!A:A)} -> 5 | J6: {=XLOOKUP(TO!$B6,SETORES!B:B,SETORES!A:A)} -> 1
A7: ARPA | B7: SA-01 | C7: 5 | E7: 10 | G7: parametros | H7: 6 | I7: {=XLOOKUP(TO!$A7,MACROZONAS!B:B,MACROZONAS!A:A)} -> 6 | J7: {=XLOOKUP(TO!$B7,SETORES!B:B,SETORES!A:A)} -> 1
A8: ARUC | B8: SA-01 | C8: 10 | E8: 10 | G8: parametros | H8: 7 | I8: {=XLOOKUP(TO!$A8,MACROZONAS!B:B,MACROZONAS!A:A)} -> 7 | J8: {=XLOOKUP(TO!$B8,SETORES!B:B,SETORES!A:A)} -> 1
A9: AUAP | B9: SA-02 | C9: 60 | E9: 10 | G9: parametros | H9: 8 | I9: {=XLOOKUP(TO!$A9,MACROZONAS!B:B,MACROZONAS!A:A)} -> 1 | J9: {=XLOOKUP(TO!$B9,SETORES!B:B,SETORES!A:A)} -> 2
A10: AUAS | B10: SA-02 | C10: 60 | E10: 10 | G10: parametros | H10: 9 | I10: {=XLOOKUP(TO!$A10,MACROZONAS!B:B,MACROZONAS!A:A)} -> 2 | J10: {=XLOOKUP(TO!$B10,SETORES!B:B,SETORES!A:A)} -> 2
A11: AUAC | B11: SA-02 | C11: 60 | E11: 10 | G11: parametros | H11: 10 | I11: {=XLOOKUP(TO!$A11,MACROZONAS!B:B,MACROZONAS!A:A)} -> 3 | J11: {=XLOOKUP(TO!$B11,SETORES!B:B,SETORES!A:A)} -> 2
A12: AUAE | B12: SA-02 | C12: 60 | E12: 10 | G12: parametros | H12: 11 | I12: {=XLOOKUP(TO!$A12,MACROZONAS!B:B,MACROZONAS!A:A)} -> 4 | J12: {=XLOOKUP(TO!$B12,SETORES!B:B,SETORES!A:A)} -> 2
A13: AUPA | B13: SA-02 | C13: 10 | E13: 10 | G13: parametros | H13: 12 | I13: {=XLOOKUP(TO!$A13,MACROZONAS!B:B,MACROZONAS!A:A)} -> 5 | J13: {=XLOOKUP(TO!$B13,SETORES!B:B,SETORES!A:A)} -> 2
... A120: ARUC | B120: FR | C120: 10 | E120: 10 | G120: parametros | H120: 119 | I120: {=XLOOKUP(TO!$A120,MACROZONAS!B:B,MACROZONAS!A:A)} -> 7 | J120: {=XLOOKUP(TO!$B120,SETORES!B:B,SETORES!A:A)} -> 17

Sheet RECUO
A1: macrozona | B1: setor | C1: recuo | D1: obs_setor | E1: obs_coef | F1: obs_geral | G1: obs_tabela | H1: recuo_id | I1: recuo_macrozona_id | J1: recuo_setor_id
A2: AUAP | B2: SA-01 | C2: 5 | D2: 7 | E2: 10 | G2: parametros | H2: 1 | I2: {=XLOOKUP(RECUO!$A2,MACROZONAS!B:B,MACROZONAS!A:A)} -> 1 | J2: {=XLOOKUP(RECUO!$B2,SETORES!B:B,SETORES!A:A)} -> 1
A3: AUAS | B3: SA-01 | C3: 5 | D3: 7 | E3: 10 | G3: parametros | H3: 2 | I3: {=XLOOKUP(RECUO!$A3,MACROZONAS!B:B,MACROZONAS!A:A)} -> 2 | J3: {=XLOOKUP(RECUO!$B3,SETORES!B:B,SETORES!A:A)} -> 1
A4: AUAC | B4: SA-01 | C4: 5 | D4: 7 | E4: 10 | G4: parametros | H4: 3 | I4: {=XLOOKUP(RECUO!$A4,MACROZONAS!B:B,MACROZONAS!A:A)} -> 3 | J4: {=XLOOKUP(RECUO!$B4,SETORES!B:B,SETORES!A:A)} -> 1
A5: AUAE | B5: SA-01 | C5: 5 | D5: 7 | E5: 10 | G5: parametros | H5: 4 | I5: {=XLOOKUP(RECUO!$A5,MACROZONAS!B:B,MACROZONAS!A:A)} -> 4 | J5: {=XLOOKUP(RECUO!$B5,SETORES!B:B,SETORES!A:A)} -> 1
A6: AUPA | B6: SA-01 | C6: 10 | E6: 10 | G6: parametros | H6: 5 | I6: {=XLOOKUP(RECUO!$A6,MACROZONAS!B:B,MACROZONAS!A:A)} -> 5 | J6: {=XLOOKUP(RECUO!$B6,SETORES!B:B,SETORES!A:A)} -> 1
A7: ARPA | B7: SA-01 | C7: 10 | E7: 10 | G7: parametros | H7: 6 | I7: {=XLOOKUP(RECUO!$A7,MACROZONAS!B:B,MACROZONAS!A:A)} -> 6 | J7: {=XLOOKUP(RECUO!$B7,SETORES!B:B,SETORES!A:A)} -> 1
A8: ARUC | B8: SA-01 | C8: 10 | E8: 10 | G8: parametros | H8: 7 | I8: {=XLOOKUP(RECUO!$A8,MACROZONAS!B:B,MACROZONAS!A:A)} -> 7 | J8: {=XLOOKUP(RECUO!$B8,SETORES!B:B,SETORES!A:A)} -> 1
A9: AUAP | B9: SA-02 | C9: 5 | D9: 7 | E9: 10 | G9: parametros | H9: 8 | I9: {=XLOOKUP(RECUO!$A9,MACROZONAS!B:B,MACROZONAS!A:A)} -> 1 | J9: {=XLOOKUP(RECUO!$B9,SETORES!B:B,SETORES!A:A)} -> 2
A10: AUAS | B10: SA-02 | C10: 5 | D10: 7 | E10: 10 | G10: parametros | H10: 9 | I10: {=XLOOKUP(RECUO!$A10,MACROZONAS!B:B,MACROZONAS!A:A)} -> 2 | J10: {=XLOOKUP(RECUO!$B10,SETORES!B:B,SETORES!A:A)} -> 2
A11: AUAC | B11: SA-02 | C11: 5 | D11: 7 | E11: 10 | G11: parametros | H11: 10 | I11: {=XLOOKUP(RECUO!$A11,MACROZONAS!B:B,MACROZONAS!A:A)} -> 3 | J11: {=XLOOKUP(RECUO!$B11,SETORES!B:B,SETORES!A:A)} -> 2
A12: AUAE | B12: SA-02 | C12: 5 | D12: 7 | E12: 10 | G12: parametros | H12: 11 | I12: {=XLOOKUP(RECUO!$A12,MACROZONAS!B:B,MACROZONAS!A:A)} -> 4 | J12: {=XLOOKUP(RECUO!$B12,SETORES!B:B,SETORES!A:A)} -> 2
A13: AUPA | B13: SA-02 | C13: 10 | E13: 10 | G13: parametros | H13: 12 | I13: {=XLOOKUP(RECUO!$A13,MACROZONAS!B:B,MACROZONAS!A:A)} -> 5 | J13: {=XLOOKUP(RECUO!$B13,SETORES!B:B,SETORES!A:A)} -> 2
A14: ARPA | B14: SA-02 | C14: 10 | E14: 10 | G14: parametros | H14: 13 | I14: {=XLOOKUP(RECUO!$A14,MACROZONAS!B:B,MACROZONAS!A:A)} -> 6 | J14: {=XLOOKUP(RECUO!$B14,SETORES!B:B,SETORES!A:A)} -> 2
A15: ARUC | B15: SA-02 | C15: 10 | E15: 10 | G15: parametros | H15: 14 | I15: {=XLOOKUP(RECUO!$A15,MACROZONAS!B:B,MACROZONAS!A:A)} -> 7 | J15: {=XLOOKUP(RECUO!$B15,SETORES!B:B,SETORES!A:A)} -> 2
A16: AUAP | B16: SA-03 | C16: 5 | D16: 7 | E16: 10 | G16: parametros | H16: 15 | I16: {=XLOOKUP(RECUO!$A16,MACROZONAS!B:B,MACROZONAS!A:A)} -> 1 | J16: {=XLOOKUP(RECUO!$B16,SETORES!B:B,SETORES!A:A)} -> 3
A17: AUAS | B17: SA-03 | C17: 5 | D17: 7 | E17: 10 | G17: parametros | H17: 16 | I17: {=XLOOKUP(RECUO!$A17,MACROZONAS!B:B,MACROZONAS!A:A)} -> 2 | J17: {=XLOOKUP(RECUO!$B17,SETORES!B:B,SETORES!A:A)} -> 3
A18: AUAC | B18: SA-03 | C18: 5 | D18: 7 | E18: 10 | G18: parametros | H18: 17 | I18: {=XLOOKUP(RECUO!$A18,MACROZONAS!B:B,MACROZONAS!A:A)} -> 3 | J18: {=XLOOKUP(RECUO!$B18,SETORES!B:B,SETORES!A:A)} -> 3
A19: AUAE | B19: SA-03 | C19: 5 | D19: 7 | E19: 10 | G19: parametros | H19: 18 | I19: {=XLOOKUP(RECUO!$A19,MACROZONAS!B:B,MACROZONAS!A:A)} -> 4 | J19: {=XLOOKUP(RECUO!$B19,SETORES!B:B,SETORES!A:A)} -> 3
A20: AUPA | B20: SA-03 | C20: 10 | E20: 10 | G20: parametros | H20: 19 | I20: {=XLOOKUP(RECUO!$A20,MACROZONAS!B:B,MACROZONAS!A:A)} -> 5 | J20: {=XLOOKUP(RECUO!$B20,SETORES!B:B,SETORES!A:A)} -> 3
A21: ARPA | B21: SA-03 | C21: 10 | E21: 10 | G21: parametros | H21: 20 | I21: {=XLOOKUP(RECUO!$A21,MACROZONAS!B:B,MACROZONAS!A:A)} -> 6 | J21: {=XLOOKUP(RECUO!$B21,SETORES!B:B,SETORES!A:A)} -> 3
A22: ARUC | B22: SA-03 | C22: 10 | E22: 10 | G22: parametros | H22: 21 | I22: {=XLOOKUP(RECUO!$A22,MACROZONAS!B:B,MACROZONAS!A:A)} -> 7 | J22: {=XLOOKUP(RECUO!$B22,SETORES!B:B,SETORES!A:A)} -> 3
A23: AUAP | B23: SA-04 | C23: 5 | D23: 7 | E23: 10 | G23: parametros | H23: 22 | I23: {=XLOOKUP(RECUO!$A23,MACROZONAS!B:B,MACROZONAS!A:A)} -> 1 | J23: {=XLOOKUP(RECUO!$B23,SETORES!B:B,SETORES!A:A)} -> 4
A24: AUAS | B24: SA-04 | C24: 5 | D24: 7 | E24: 10 | G24: parametros | H24: 23 | I24: {=XLOOKUP(RECUO!$A24,MACROZONAS!B:B,MACROZONAS!A:A)} -> 2 | J24: {=XLOOKUP(RECUO!$B24,SETORES!B:B,SETORES!A:A)} -> 4
A25: AUAC | B25: SA-04 | C25: 5 | D25: 7 | E25: 10 | G25: parametros | H25: 24 | I25: {=XLOOKUP(RECUO!$A25,MACROZONAS!B:B,MACROZONAS!A:A)} -> 3 | J25: {=XLOOKUP(RECUO!$B25,SETORES!B:B,SETORES!A:A)} -> 4
A26: AUAE | B26: SA-04 | C26: 5 | D26: 7 | E26: 10 | G26: parametros | H26: 25 | I26: {=XLOOKUP(RECUO!$A26,MACROZONAS!B:B,MACROZONAS!A:A)} -> 4 | J26: {=XLOOKUP(RECUO!$B26,SETORES!B:B,SETORES!A:A)} -> 4
A27: AUPA | B27: SA-04 | C27: 10 | E27: 10 | G27: parametros | H27: 26 | I27: {=XLOOKUP(RECUO!$A27,MACROZONAS!B:B,MACROZONAS!A:A)} -> 5 | J27: {=XLOOKUP(RECUO!$B27,SETORES!B:B,SETORES!A:A)} -> 4
A28: ARPA | B28: SA-04 | C28: 10 | E28: 10 | G28: parametros | H28: 27 | I28: {=XLOOKUP(RECUO!$A28,MACROZONAS!B:B,MACROZONAS!A:A)} -> 6 | J28: {=XLOOKUP(RECUO!$B28,SETORES!B:B,SETORES!A:A)} -> 4
A29: ARUC | B29: SA-04 | C29: 10 | E29: 10 | G29: parametros | H29: 28 | I29: {=XLOOKUP(RECUO!$A29,MACROZONAS!B:B,MACROZONAS!A:A)} -> 7 | J29: {=XLOOKUP(RECUO!$B29,SETORES!B:B,SETORES!A:A)} -> 4
A30: AUAP | B30: SA-05 | C30: 5 | D30: 7 | E30: 10 | G30: parametros | H30: 29 | I30: {=XLOOKUP(RECUO!$A30,MACROZONAS!B:B,MACROZONAS!A:A)} -> 1 | J30: {=XLOOKUP(RECUO!$B30,SETORES!B:B,SETORES!A:A)} -> 5
A31: AUAS | B31: SA-05 | C31: 5 | D31: 7 | E31: 10 | G31: parametros | H31: 30 | I31: {=XLOOKUP(RECUO!$A31,MACROZONAS!B:B,MACROZONAS!A:A)} -> 2 | J31: {=XLOOKUP(RECUO!$B31,SETORES!B:B,SETORES!A:A)} -> 5
A32: AUAC | B32: SA-05 | C32: 5 | D32: 7 | E32: 10 | G32: parametros | H32: 31 | I32: {=XLOOKUP(RECUO!$A32,MACROZONAS!B:B,MACROZONAS!A:A)} -> 3 | J32: {=XLOOKUP(RECUO!$B32,SETORES!B:B,SETORES!A:A)} -> 5
A33: AUAE | B33: SA-05 | C33: 5 | D33: 7 | E33: 10 | G33: parametros | H33: 32 | I33: {=XLOOKUP(RECUO!$A33,MACROZONAS!B:B,MACROZONAS!A:A)} -> 4 | J33: {=XLOOKUP(RECUO!$B33,SETORES!B:B,SETORES!A:A)} -> 5
A34: AUPA | B34: SA-05 | C34: 10 | E34: 10 | G34: parametros | H34: 33 | I34: {=XLOOKUP(RECUO!$A34,MACROZONAS!B:B,MACROZONAS!A:A)} -> 5 | J34: {=XLOOKUP(RECUO!$B34,SETORES!B:B,SETORES!A:A)} -> 5
A35: ARPA | B35: SA-05 | C35: 10 | E35: 10 | G35: parametros | H35: 34 | I35: {=XLOOKUP(RECUO!$A35,MACROZONAS!B:B,MACROZONAS!A:A)} -> 6 | J35: {=XLOOKUP(RECUO!$B35,SETORES!B:B,SETORES!A:A)} -> 5
A36: ARUC | B36: SA-05 | C36: 10 | E36: 10 | G36: parametros | H36: 35 | I36: {=XLOOKUP(RECUO!$A36,MACROZONAS!B:B,MACROZONAS!A:A)} -> 7 | J36: {=XLOOKUP(RECUO!$B36,SETORES!B:B,SETORES!A:A)} -> 5
A37: AUAP | B37: SAR | C37: 5 | D37: 7 | E37: 10 | G37: parametros | H37: 36 | I37: {=XLOOKUP(RECUO!$A37,MACROZONAS!B:B,MACROZONAS!A:A)} -> 1 | J37: {=XLOOKUP(RECUO!$B37,SETORES!B:B,SETORES!A:A)} -> 6
A38: AUAS | B38: SAR | C38: 5 | D38: 7 | E38: 10 | G38: parametros | H38: 37 | I38: {=XLOOKUP(RECUO!$A38,MACROZONAS!B:B,MACROZONAS!A:A)} -> 2 | J38: {=XLOOKUP(RECUO!$B38,SETORES!B:B,SETORES!A:A)} -> 6
A39: AUAC | B39: SAR | C39: 5 | D39: 7 | E39: 10 | G39: parametros | H39: 38 | I39: {=XLOOKUP(RECUO!$A39,MACROZONAS!B:B,MACROZONAS!A:A)} -> 3 | J39: {=XLOOKUP(RECUO!$B39,SETORES!B:B,SETORES!A:A)} -> 6
A40: AUAE | B40: SAR | C40: 5 | D40: 7 | E40: 10 | G40: parametros | H40: 39 | I40: {=XLOOKUP(RECUO!$A40,MACROZONAS!B:B,MACROZONAS!A:A)} -> 4 | J40: {=XLOOKUP(RECUO!$B40,SETORES!B:B,SETORES!A:A)} -> 6
...

Sheet REC.L.F
A1: macrozona | B1: setor | C1: recuo_lateral | D1: divisor | E1: minimo | F1: acrescimo | G1: obs_setor | H1: obs_coef | I1: obs_geral | J1: obs_tabela | K1: recLF_id | L1: recLF_macrozona_id | M1: recLF_setor_id
A2: AUAP | B2: SA-01 | C2: h/6 + 0,5 | D2: 6 | E2: 1.5 | F2: 0.5 | G2: 7 | H2: 4, 10, 18 | J2: parametros | K2: 1 | L2: {=XLOOKUP(REC.L.F!$A2,MACROZONAS!B:B,MACROZONAS!A:A)} -> 1 | M2: {=XLOOKUP(REC.L.F!$B2,SETORES!B:B,SETORES!A:A)} -> 1
A3: AUAS | B3: SA-01 | C3: h/6 + 0,5 | D3: 6 | E3: 1.5 | F3: 0.5 | G3: 7 | H3: 4, 10, 18 | J3: parametros | K3: 2 | L3: {=XLOOKUP(REC.L.F!$A3,MACROZONAS!B:B,MACROZONAS!A:A)} -> 2 | M3: {=XLOOKUP(REC.L.F!$B3,SETORES!B:B,SETORES!A:A)} -> 1
A4: AUAC | B4: SA-01 | C4: h/6 + 0,5 | D4: 6 | E4: 1.5 | F4: 0.5 | G4: 7 | H4: 4, 10, 18 | J4: parametros | K4: 3 | L4: {=XLOOKUP(REC.L.F!$A4,MACROZONAS!B:B,MACROZONAS!A:A)} -> 3 | M4: {=XLOOKUP(REC.L.F!$B4,SETORES!B:B,SETORES!A:A)} -> 1
A5: AUAE | B5: SA-01 | C5: h/6 + 0,5 | D5: 6 | E5: 1.5 | F5: 0.5 | G5: 7 | H5: 4, 10, 18 | J5: parametros | K5: 4 | L5: {=XLOOKUP(REC.L.F!$A5,MACROZONAS!B:B,MACROZONAS!A:A)} -> 4 | M5: {=XLOOKUP(REC.L.F!$B5,SETORES!B:B,SETORES!A:A)} -> 1
A6: AUPA | B6: SA-01 | C6: 5 | E6: 5 | H6: 4, 10, 18 | J6: parametros | K6: 5 | L6: {=XLOOKUP(REC.L.F!$A6,MACROZONAS!B:B,MACROZONAS!A:A)} -> 5 | M6: {=XLOOKUP(REC.L.F!$B6,SETORES!B:B,SETORES!A:A)} -> 1
A7: ARPA | B7: SA-01 | C7: 5 | E7: 5 | H7: 4, 10, 18 | J7: parametros | K7: 6 | L7: {=XLOOKUP(REC.L.F!$A7,MACROZONAS!B:B,MACROZONAS!A:A)} -> 6 | M7: {=XLOOKUP(REC.L.F!$B7,SETORES!B:B,SETORES!A:A)} -> 1
A8: ARUC | B8: SA-01 | C8: 5 | E8: 5 | H8: 4, 10, 18 | J8: parametros | K8: 7 | L8: {=XLOOKUP(REC.L.F!$A8,MACROZONAS!B:B,MACROZONAS!A:A)} -> 7 | M8: {=XLOOKUP(REC.L.F!$B8,SETORES!B:B,SETORES!A:A)} -> 1
A9: AUAP | B9: SA-02 | C9: h/6 + 0,5 | D9: 6 | E9: 1.5 | F9: 0.5 | G9: 7 | H9: 4, 10, 18 | J9: parametros | K9: 8 | L9: {=XLOOKUP(REC.L.F!$A9,MACROZONAS!B:B,MACROZONAS!A:A)} -> 1 | M9: {=XLOOKUP(REC.L.F!$B9,SETORES!B:B,SETORES!A:A)} -> 2
A10: AUAS | B10: SA-02 | C10: h/6 + 0,5 | D10: 6 | E10: 1.5 | F10: 0.5 | G10: 7 | H10: 4, 10, 18 | J10: parametros | K10: 9 | L10: {=XLOOKUP(REC.L.F!$A10,MACROZONAS!B:B,MACROZONAS!A:A)} -> 2 | M10: {=XLOOKUP(REC.L.F!$B10,SETORES!B:B,SETORES!A:A)} -> 2
A11: AUAC | B11: SA-02 | C11: h/6 + 0,5 | D11: 6 | E11: 1.5 | F11: 0.5 | G11: 7 | H11: 4, 10, 18 | J11: parametros | K11: 10 | L11: {=XLOOKUP(REC.L.F!$A11,MACROZONAS!B:B,MACROZONAS!A:A)} -> 3 | M11: {=XLOOKUP(REC.L.F!$B11,SETORES!B:B,SETORES!A:A)} -> 2
A12: AUAE | B12: SA-02 | C12: h/6 + 0,5 | D12: 6 | E12: 1.5 | F12: 0.5 | G12: 7 | H12: 4, 10, 18 | J12: parametros | K12: 11 | L12: {=XLOOKUP(REC.L.F!$A12,MACROZONAS!B:B,MACROZONAS!A:A)} -> 4 | M12: {=XLOOKUP(REC.L.F!$B12,SETORES!B:B,SETORES!A:A)} -> 2
A13: AUPA | B13: SA-02 | C13: 5 | E13: 5 | H13: 4, 10, 18 | J13: parametros | K13: 12 | L13: {=XLOOKUP(REC.L.F!$A13,MACROZONAS!B:B,MACROZONAS!A:A)} -> 5 | M13: {=XLOOKUP(REC.L.F!$B13,SETORES!B:B,SETORES!A:A)} -> 2
A14: ARPA | B14: SA-02 | C14: 5 | E14: 5 | H14: 4, 10, 18 | J14: parametros | K14: 13 | L14: {=XLOOKUP(REC.L.F!$A14,MACROZONAS!B:B,MACROZONAS!A:A)} -> 6 | M14: {=XLOOKUP(REC.L.F!$B14,SETORES!B:B,SETORES!A:A)} -> 2
A15: ARUC | B15: SA-02 | C15: 5 | E15: 5 | H15: 4, 10, 18 | J15: parametros | K15: 14 | L15: {=XLOOKUP(REC.L.F!$A15,MACROZONAS!B:B,MACROZONAS!A:A)} -> 7 | M15: {=XLOOKUP(REC.L.F!$B15,SETORES!B:B,SETORES!A:A)} -> 2
A16: AUAP | B16: SA-03 | C16: h/6 + 0,5 | D16: 6 | E16: 1.5 | F16: 0.5 | G16: 7 | H16: 4, 10, 18 | J16: parametros | K16: 15 | L16: {=XLOOKUP(REC.L.F!$A16,MACROZONAS!B:B,MACROZONAS!A:A)} -> 1 | M16: {=XLOOKUP(REC.L.F!$B16,SETORES!B:B,SETORES!A:A)} -> 3
A17: AUAS | B17: SA-03 | C17: h/6 + 0,5 | D17: 6 | E17: 1.5 | F17: 0.5 | G17: 7 | H17: 4, 10, 18 | J17: parametros | K17: 16 | L17: {=XLOOKUP(REC.L.F!$A17,MACROZONAS!B:B,MACROZONAS!A:A)} -> 2 | M17: {=XLOOKUP(REC.L.F!$B17,SETORES!B:B,SETORES!A:A)} -> 3
A18: AUAC | B18: SA-03 | C18: h/6 + 0,5 | D18: 6 | E18: 1.5 | F18: 0.5 | G18: 7 | H18: 4, 10, 18 | J18: parametros | K18: 17 | L18: {=XLOOKUP(REC.L.F!$A18,MACROZONAS!B:B,MACROZONAS!A:A)} -> 3 | M18: {=XLOOKUP(REC.L.F!$B18,SETORES!B:B,SETORES!A:A)} -> 3
A19: AUAE | B19: SA-03 | C19: h/6 + 0,5 | D19: 6 | E19: 1.5 | F19: 0.5 | G19: 7 | H19: 4, 10, 18 | J19: parametros | K19: 18 | L19: {=XLOOKUP(REC.L.F!$A19,MACROZONAS!B:B,MACROZONAS!A:A)} -> 4 | M19: {=XLOOKUP(REC.L.F!$B19,SETORES!B:B,SETORES!A:A)} -> 3
A20: AUPA | B20: SA-03 | C20: 5 | E20: 5 | H20: 4, 10, 18 | J20: parametros | K20: 19 | L20: {=XLOOKUP(REC.L.F!$A20,MACROZONAS!B:B,MACROZONAS!A:A)} -> 5 | M20: {=XLOOKUP(REC.L.F!$B20,SETORES!B:B,SETORES!A:A)} -> 3
A21: ARPA | B21: SA-03 | C21: 5 | E21: 5 | H21: 4, 10, 18 | J21: parametros | K21: 20 | L21: {=XLOOKUP(REC.L.F!$A21,MACROZONAS!B:B,MACROZONAS!A:A)} -> 6 | M21: {=XLOOKUP(REC.L.F!$B21,SETORES!B:B,SETORES!A:A)} -> 3
A22: ARUC | B22: SA-03 | C22: 5 | E22: 5 | H22: 4, 10, 18 | J22: parametros | K22: 21 | L22: {=XLOOKUP(REC.L.F!$A22,MACROZONAS!B:B,MACROZONAS!A:A)} -> 7 | M22: {=XLOOKUP(REC.L.F!$B22,SETORES!B:B,SETORES!A:A)} -> 3
A23: AUAP | B23: SA-04 | C23: h/6 + 0,5 | D23: 6 | E23: 1.5 | F23: 0.5 | G23: 7 | H23: 4, 10, 18 | J23: parametros | K23: 22 | L23: {=XLOOKUP(REC.L.F!$A23,MACROZONAS!B:B,MACROZONAS!A:A)} -> 1 | M23: {=XLOOKUP(REC.L.F!$B23,SETORES!B:B,SETORES!A:A)} -> 4
A24: AUAS | B24: SA-04 | C24: h/6 + 0,5 | D24: 6 | E24: 1.5 | F24: 0.5 | G24: 7 | H24: 4, 10, 18 | J24: parametros | K24: 23 | L24: {=XLOOKUP(REC.L.F!$A24,MACROZONAS!B:B,MACROZONAS!A:A)} -> 2 | M24: {=XLOOKUP(REC.L.F!$B24,SETORES!B:B,SETORES!A:A)} -> 4
A25: AUAC | B25: SA-04 | C25: h/6 + 0,5 | D25: 6 | E25: 1.5 | F25: 0.5 | G25: 7 | H25: 4, 10, 18 | J25: parametros | K25: 24 | L25: {=XLOOKUP(REC.L.F!$A25,MACROZONAS!B:B,MACROZONAS!A:A)} -> 3 | M25: {=XLOOKUP(REC.L.F!$B25,SETORES!B:B,SETORES!A:A)} -> 4
A26: AUAE | B26: SA-04 | C26: h/6 + 0,5 | D26: 6 | E26: 1.5 | F26: 0.5 | G26: 7 | H26: 4, 10, 18 | J26: parametros | K26: 25 | L26: {=XLOOKUP(REC.L.F!$A26,MACROZONAS!B:B,MACROZONAS!A:A)} -> 4 | M26: {=XLOOKUP(REC.L.F!$B26,SETORES!B:B,SETORES!A:A)} -> 4
A27: AUPA | B27: SA-04 | C27: 5 | E27: 5 | H27: 4, 10, 18 | J27: parametros | K27: 26 | L27: {=XLOOKUP(REC.L.F!$A27,MACROZONAS!B:B,MACROZONAS!A:A)} -> 5 | M27: {=XLOOKUP(REC.L.F!$B27,SETORES!B:B,SETORES!A:A)} -> 4
A28: ARPA | B28: SA-04 | C28: 5 | E28: 5 | H28: 4, 10, 18 | J28: parametros | K28: 27 | L28: {=XLOOKUP(REC.L.F!$A28,MACROZONAS!B:B,MACROZONAS!A:A)} -> 6 | M28: {=XLOOKUP(REC.L.F!$B28,SETORES!B:B,SETORES!A:A)} -> 4
A29: ARUC | B29: SA-04 | C29: 5 | E29: 5 | H29: 4, 10, 18 | J29: parametros | K29: 28 | L29: {=XLOOKUP(REC.L.F!$A29,MACROZONAS!B:B,MACROZONAS!A:A)} -> 7 | M29: {=XLOOKUP(REC.L.F!$B29,SETORES!B:B,SETORES!A:A)} -> 4
A30: AUAP | B30: SA-05 | C30: h/6 + 0,5 | D30: 6 | E30: 1.5 | F30: 0.5 | G30: 7 | H30: 4, 10, 18 | J30: parametros | K30: 29 | L30: {=XLOOKUP(REC.L.F!$A30,MACROZONAS!B:B,MACROZONAS!A:A)} -> 1 | M30: {=XLOOKUP(REC.L.F!$B30,SETORES!B:B,SETORES!A:A)} -> 5
A31: AUAS | B31: SA-05 | C31: h/6 + 0,5 | D31: 6 | E31: 1.5 | F31: 0.5 | G31: 7 | H31: 4, 10, 18 | J31: parametros | K31: 30 | L31: {=XLOOKUP(REC.L.F!$A31,MACROZONAS!B:B,MACROZONAS!A:A)} -> 2 | M31: {=XLOOKUP(REC.L.F!$B31,SETORES!B:B,SETORES!A:A)} -> 5
A32: AUAC | B32: SA-05 | C32: h/6 + 0,5 | D32: 6 | E32: 1.5 | F32: 0.5 | G32: 7 | H32: 4, 10, 18 | J32: parametros | K32: 31 | L32: {=XLOOKUP(REC.L.F!$A32,MACROZONAS!B:B,MACROZONAS!A:A)} -> 3 | M32: {=XLOOKUP(REC.L.F!$B32,SETORES!B:B,SETORES!A:A)} -> 5
A33: AUAE | B33: SA-05 | C33: h/6 + 0,5 | D33: 6 | E33: 1.5 | F33: 0.5 | G33: 7 | H33: 4, 10, 18 | J33: parametros | K33: 32 | L33: {=XLOOKUP(REC.L.F!$A33,MACROZONAS!B:B,MACROZONAS!A:A)} -> 4 | M33: {=XLOOKUP(REC.L.F!$B33,SETORES!B:B,SETORES!A:A)} -> 5
A34: AUPA | B34: SA-05 | C34: 5 | E34: 5 | H34: 4, 10, 18 | J34: parametros | K34: 33 | L34: {=XLOOKUP(REC.L.F!$A34,MACROZONAS!B:B,MACROZONAS!A:A)} -> 5 | M34: {=XLOOKUP(REC.L.F!$B34,SETORES!B:B,SETORES!A:A)} -> 5
A35: ARPA | B35: SA-05 | C35: 5 | E35: 5 | H35: 4, 10, 18 | J35: parametros | K35: 34 | L35: {=XLOOKUP(REC.L.F!$A35,MACROZONAS!B:B,MACROZONAS!A:A)} -> 6 | M35: {=XLOOKUP(REC.L.F!$B35,SETORES!B:B,SETORES!A:A)} -> 5
A36: ARUC | B36: SA-05 | C36: 5 | E36: 5 | H36: 4, 10, 18 | J36: parametros | K36: 35 | L36: {=XLOOKUP(REC.L.F!$A36,MACROZONAS!B:B,MACROZONAS!A:A)} -> 7 | M36: {=XLOOKUP(REC.L.F!$B36,SETORES!B:B,SETORES!A:A)} -> 5
A37: AUAP | B37: SAR | C37: h/6 + 0,5 | D37: 6 | E37: 1.5 | F37: 0.5 | G37: 7 | H37: 4, 10, 18 | J37: parametros | K37: 36 | L37: {=XLOOKUP(REC.L.F!$A37,MACROZONAS!B:B,MACROZONAS!A:A)} -> 1 | M37: {=XLOOKUP(REC.L.F!$B37,SETORES!B:B,SETORES!A:A)} -> 6
A38: AUAS | B38: SAR | C38: h/6 + 0,5 | D38: 6 | E38: 1.5 | F38: 0.5 | G38: 7 | H38: 4, 10, 18 | J38: parametros | K38: 37 | L38: {=XLOOKUP(REC.L.F!$A38,MACROZONAS!B:B,MACROZONAS!A:A)} -> 2 | M38: {=XLOOKUP(REC.L.F!$B38,SETORES!B:B,SETORES!A:A)} -> 6
A39: AUAC | B39: SAR | C39: h/6 + 0,5 | D39: 6 | E39: 1.5 | F39: 0.5 | G39: 7 | H39: 4, 10, 18 | J39: parametros | K39: 38 | L39: {=XLOOKUP(REC.L.F!$A39,MACROZONAS!B:B,MACROZONAS!A:A)} -> 3 | M39: {=XLOOKUP(REC.L.F!$B39,SETORES!B:B,SETORES!A:A)} -> 6
A40: AUAE | B40: SAR | C40: h/6 + 0,5 | D40: 6 | E40: 1.5 | F40: 0.5 | G40: 7 | H40: 4, 10, 18 | J40: parametros | K40: 39 | L40: {=XLOOKUP(REC.L.F!$A40,MACROZONAS!B:B,MACROZONAS!A:A)} -> 4 | M40: {=XLOOKUP(REC.L.F!$B40,SETORES!B:B,SETORES!A:A)} -> 6
...

Sheet TP
A1: macrozona | B1: setor | C1: tp | D1: obs_setor | E1: obs_coef | F1: obs_geral | G1: obs_tabela | H1: permeabilidade_id | I1: permeabiliade_macrozona_id | J1: permeabilidade_setor_id
A2: ARPA | B2: FR | C2: 80 | E2: 8 | G2: parametros | H2: 1 | I2: {=XLOOKUP(TP!$A2,MACROZONAS!B:B,MACROZONAS!A:A)} -> 6 | J2: {=XLOOKUP(TP!$B2,SETORES!B:B,SETORES!A:A)} -> 17
A3: ARUC | B3: FR | C3: 80 | E3: 8 | G3: parametros | H3: 2 | I3: {=XLOOKUP(TP!$A3,MACROZONAS!B:B,MACROZONAS!A:A)} -> 7 | J3: {=XLOOKUP(TP!$B3,SETORES!B:B,SETORES!A:A)} -> 17
A4: AUAC | B4: FR | C4: 20 | E4: 8 | G4: parametros | H4: 3 | I4: {=XLOOKUP(TP!$A4,MACROZONAS!B:B,MACROZONAS!A:A)} -> 3 | J4: {=XLOOKUP(TP!$B4,SETORES!B:B,SETORES!A:A)} -> 17
A5: AUAE | B5: FR | C5: 20 | E5: 8 | G5: parametros | H5: 4 | I5: {=XLOOKUP(TP!$A5,MACROZONAS!B:B,MACROZONAS!A:A)} -> 4 | J5: {=XLOOKUP(TP!$B5,SETORES!B:B,SETORES!A:A)} -> 17
A6: AUAP | B6: FR | C6: 20 | E6: 8 | G6: parametros | H6: 5 | I6: {=XLOOKUP(TP!$A6,MACROZONAS!B:B,MACROZONAS!A:A)} -> 1 | J6: {=XLOOKUP(TP!$B6,SETORES!B:B,SETORES!A:A)} -> 17
A7: AUAS | B7: FR | C7: 20 | E7: 8 | G7: parametros | H7: 6 | I7: {=XLOOKUP(TP!$A7,MACROZONAS!B:B,MACROZONAS!A:A)} -> 2 | J7: {=XLOOKUP(TP!$B7,SETORES!B:B,SETORES!A:A)} -> 17
A8: AUPA | B8: FR | C8: 80 | E8: 8 | G8: parametros | H8: 7 | I8: {=XLOOKUP(TP!$A8,MACROZONAS!B:B,MACROZONAS!A:A)} -> 5 | J8: {=XLOOKUP(TP!$B8,SETORES!B:B,SETORES!A:A)} -> 17
A9: ARPA | B9: FV | C9: 80 | E9: 8 | G9: parametros | H9: 8 | I9: {=XLOOKUP(TP!$A9,MACROZONAS!B:B,MACROZONAS!A:A)} -> 6 | J9: {=XLOOKUP(TP!$B9,SETORES!B:B,SETORES!A:A)} -> 16
A10: ARUC | B10: FV | C10: 80 | E10: 8 | G10: parametros | H10: 9 | I10: {=XLOOKUP(TP!$A10,MACROZONAS!B:B,MACROZONAS!A:A)} -> 7 | J10: {=XLOOKUP(TP!$B10,SETORES!B:B,SETORES!A:A)} -> 16
A11: AUAC | B11: FV | C11: 20 | E11: 8 | G11: parametros | H11: 10 | I11: {=XLOOKUP(TP!$A11,MACROZONAS!B:B,MACROZONAS!A:A)} -> 3 | J11: {=XLOOKUP(TP!$B11,SETORES!B:B,SETORES!A:A)} -> 16
